Workbook
Name ageOfRetirement: Assumptions!$B$14
Name annualBudget: Assumptions!$B$71
Name assetReturn: Assumptions!$B$10
Name assetsSaveShare: Assumptions!$B$48
Name benefitRound: Assumptions!$B$74
Name CASH_SAVINGS_SHARE: Assumptions!$B$51
Name CI_COST: Assumptions!$B$35
Name CI_YEARS: Assumptions!$B$34
Name coverPremRoundStep: Assumptions!$B$67
Name coverSliderPremFloor: Assumptions!$B$68
Name CPF_employee: CPF!$B$26
Name CPF_income: CPF!$B$8
Name CPF_on: CPF!$B$22
Name CPF_rate: CPF!$B$25
Name CPF_takeHome: CPF!$B$27
Name CpfCountrySwitch: CPF!$I$6:$J$14
Name cpfRate_over70: CPF!$B$16
Name cpfRate_to55: CPF!$B$12
Name cpfRate_to60: CPF!$B$13
Name cpfRate_to65: CPF!$B$14
Name cpfRate_to70: CPF!$B$15
Name criMedicalPlaceholder: Assumptions!$B$77
Name currentYear: Assumptions!$B$16
Name EDU_TOTAL_COST: Assumptions!$B$39
Name eduYearsDefault: Assumptions!$B$40
Name endAge: Assumptions!$B$17
Name FREE_BUDGET_SHARE: Assumptions!$B$64
Name funeralLump: Assumptions!$B$76
Name FX_benefitRound: FX!$B$34
Name FX_cash: FX!$B$22
Name FX_coverPremStep: FX!$B$32
Name FX_expenseMonthly: FX!$B$21
Name FX_incomeMonthly: FX!$B$20
Name FX_investments: FX!$B$23
Name FX_liabilities: FX!$B$26
Name FX_lifeRound: FX!$B$33
Name FX_lifeSum: FX!$B$27
Name FX_lumpStep: FX!$B$30
Name FX_monthlyStep: FX!$B$31
Name FX_mortgage: FX!$B$25
Name FX_priceLevel: FX!$B$17
Name FX_property: FX!$B$24
Name FX_usdPerLocal: FX!$B$16
Name fxMode: Assumptions!$B$23
Name FxTable: FX!$I$6:$K$14
Name gfr: Assumptions!$B$73
Name HOSP_MONTHS: Assumptions!$B$38
Name HU_age: HappiU!$B$5
Name HU_alpha: HappiU!$B$49
Name HU_benefitRound: HappiU!$B$33
Name HU_beta: HappiU!$B$28
Name HU_calRet: HappiU!$B$34
Name HU_cash: HappiU!$B$10
Name HU_cash0: HappiU!$B$46
Name HU_ciDefaultYears: HappiU!$B$19
Name HU_ciMaxAge: HappiU!$B$24
Name HU_ciProp: HappiU!$B$45
Name HU_ciYears: HappiU!$B$44
Name HU_ciYearsGP: HappiU!$B$18
Name HU_col: HappiU!$B$40

Sheet Overview
A1: FinPlan360 calculation components — live code, September 2026
A2: Yellow = type here. Orange = override (leave blank to keep the calculated value). Pick the persona on the Selected persona tab; every later tab follows that id. Gold = persona input, blue = LLM, orange = user / Money-page override, green = calculated, purple = assumptions. FX converts local amounts to USD. Validation applies USD-only rules. CPF is its own tab and is on only when the country switch says so (Singapore on, others off). HappiU and Scenario Visualizer are mapped here but scored / projected in HU and SV.
A3: Component | B3: Owner | C3: Reads | D3: Writes | E3: How it calculates (code) | F3: Code | G3: Tab | H3: HTTP / UI
A4: CPF | B4: GP pipeline (Singapore only) | C4: country, residency, age, incomeMonthly. Country switch on the CPF tab. | D4: employee CPF, take-home. 0 / income when CPF is off. | E4: On only when the country table (or orange override) is TRUE. Singapore Citizen/PR: employee CPF = floor(min(gross, OW_CEILING) × age-band rate). Foreigner → 0. Any other country → off, take-home = gross. src/cpf.py. | F4: src/cpf.py | G4: CPF | H4: Inside POST /v1/predict (take-home)
A5: People Like You | B5: GP pipeline | C5: age / DOB, occupation, gender, dependents, residency. CPF box for take-home. Does not read Assumptions. | D5: incomeMonthly, expenseMonthly, cash, investments, property, mortgage, one Life Protection policy, lifeExpectancy, isSmoker. | E5: LLM proposes gross monthly income and lifestyle flags. Income is clamped to the Singapore occupation band. Employee CPF = floor(min(gross, 8000) × age-band rate); 0 if Foreigner. expenseMonthly = round(take-home × min(67.5% + 5pp × dependents, 90%), 2). Liquid assets = max(0, surplus × 12 × 0.5 × (age − 21)), then cash 15% / investments 85%. If the model says they own a home: property from income band, mortgage = round(property × 55%). Assumed life cover = max(mortgage rounded up to S$100k, 5 × annual income if dependents > 0); premium = round(sum × 0.31%). PLU liabilities (= assets × 0.7) is not the mortgage. If this step fails, predict returns 503. | F5: src/pipeline/people_like_you.py, src/cpf.py, src/predict.py _apply_plu | G5: People Like You | H5: POST /v1/predict (first of three)
A6: Need Profiler | B6: GP pipeline | C6: Age, gender, dependents, occupation, smoker, income, expense, liquid assets, PLU liabilities, hospital/ward/lifestyle/sports, car/home/travel flags. Existing cover is hard-coded 0. No Assumptions. No LLM. | D6: needs[].enabled, needs[].priority, needs[].weightageScore. Four UNIFIED types on: two protection + two growth (retirement always one of the growth pair). | E6: Twelve AI labels are scored as Σ (factor_weight × option_weight), rounded to 2 dp, then min–max scaled 0–10. Income / expense / assets / liabilities convert local × FX to USD, then retuned USD bands. Car ownership, home ownership, travel, and existing life / CI cover have factor weights but no matching weight_options, so they add 0. select_unified_top ignores top_n (app.py still passes 4). If has_property, N_PRP replaces N_SAV in the second growth slot. priority = 5 if scaled score > 7 else 3. Personal accident / motor / travel / farewell are scored and dropped. Orange Enable? columns let you force a need on or off. | F6: src/pipeline/need_profiler.py, src/pipeline/prompts/Need_profiler.json, src/app.py top_n=4 | G6: Need Profiler | H6: POST /v1/predict
A7: Need Calculator | B7: GP pipeline | C7: Money attributes, enabled needs, goal-card sliders (lifestyle, retAge, targetYear, incomeReplaceMonthly, dependYears, bequest, monthlyContribution, tagged existing), Assumptions rates, Need parameters. | D7: For every UNIFIED type: needAmount, have, gap. Copies ageOfRetirement from the retirement row. | E7: realReturn = max(0, (1 + investmentReturn) / (1 + inflationRate) − 1). N_RET = annualSpend × (1+realReturn)^T × a(realReturn, n), n = min(LE,99) − retAge. N_INC = bequest + mortgage + ordinary annuity of annual spend over supportYears = min(max(10, 50 − age), 25). N_CRI / N_TPD = annuity-due of replacement income for 3 / 5 years + S$200,000. N_HOS = income × 6. N_EDU = 75,000 × (1 + inflation)^(targetYear − thisYear). N_SAV / N_PRP = stored needAmount if > 0, else 1× / 5× annual income. Protection have = policy sum (life is seeded by PLU). Wealth have = tagged investments only, grown at realReturn; cash is never allocated. Amounts are computed for all eight types even when a need is off. Orange Enable? and slider columns are the goal-card inputs. | F7: src/pipeline/need_calculator.py evaluate_session, src/pipeline/goal_math.py, src/hu_payload.py need_existing / apply_investment_pot | G7: Need Calculator | H7: POST /v1/predict and POST /v1/needs
A8: Goal cards | B8: GP UI | C8: Last calculator row (have, gap, stored sliders). | D8: Slider fields on the need; then POST /v1/needs (debounced). Does not recompute amounts in the browser. | E8: fillNeedEdit reads stored fields. patchNeedInputs writes lifestyle / retAge / targetYear / existing / … onto the session. Retirement stays on. The Score/Plan cap of four needs is UI-only (needEdit.capEnabledNeeds); this workbook lets you switch any need. | F8: frontend/src/lib/needEdit.ts | G8: Need Calculator (slider columns) | H8: Score and Plan screens
A9: Plan Calculator | B9: GP UI | C9: Enabled needs with gap > 0, take-home surplus, Assumptions inflationRate / investmentReturn / ageOfRetirement. | D9: planSum + planPrem (protection), planMth + planLump (wealth), investMth / investLump totals, plansOff. | E9: Suggested = enabled AND gap > 0. Default planSum = round(gap). planPrem = dummy indicative round((sum × 0.00078) / 10) × 10 (future: premium-quote API). Wealth horizon = years to retirement, or targetYear − this year. Lump / monthly caps = the amount that alone grows to the gap at realReturn (round up to S$1,000 / S$50). Default monthly = round((max(0, take-home − expense) × 12 − all protection premiums) × 50% / 12 / n_wealth / 50) × 50, then min(share, cap). Default lump = 0. Orange Include? columns are plansOff. | F9: frontend/src/lib/planProducts.ts, frontend/src/lib/local.ts seedProducts | G9: Plan Calculator | H9: Plan screen (not an HTTP engine)
A10: Budget Calculator | B10: GP UI | C10: take-home, expenseMonthly, investments, included planPrem / planMth / planLump. Not the economic rates. | D10: Nothing on the session. Plan-screen affordability only. | E10: available = max(0, takeHomeMonthly − expenseMonthly). free = round(available × 0.5). monthly = round(wealth contributions + protection premiums / 12). monthlyOver = monthly − free. lumpOver = wealth lumps − investments. Separate from the HappiU envelope (annualBudget 1500). | F10: planAfford in frontend/src/lib/planProducts.ts; availableBudget in types.ts | G10: Budget Calculator | H10: Plan screen
A11: FX | B11: Workbook only (not an HTTP engine) | C11: Personas currency + effective session money fields from People Like You. | D11: USD per 1 local, and each money field in USD. Validation reads these; engines stay local. | E11: Lookup ISO code in the FX rate table (USD per 1 local unit). USD = local × rate. Example: 5,000 SGD × 0.74 = 3,700 USD; 5,000 VND × 0.000038 = 0.19 USD. Edit the rate table on this tab. People Like You still stores local currency. | F11: Workbook FX tab (no src module — validation helper) | G11: FX | H11: Not in the live pipeline
A12: HappiU | B12: HU, via GP | C12: Whole session. Assumptions rates, CPF (inside HU), riskProfile, plan fields when set. Need amounts already stored. | D12: preHappiU, postHappiU. GP does not run the Monte Carlo. | E12: GP maps the session (src/hu_payload.py). Salary is gross incomeMonthly. N_HOS is renamed N_HSP. If retirement is off, GP still sends a synthetic N_RET = expense × 12 × (lifeExpectancy − retAge). Before a plan: benefitAmount = needAmount rounded to S$50,000, budget 200. With a plan: planSum / planPrem. This workbook does not score HappiU. | F12: src/hu_payload.py → POST /v1/score → HU | G12: Assumptions (envelope only) | H12: POST /v1/score
A13: Scenario Visualizer | B13: SV, via GP | C13: Session after Plan, all six rates, ageOfRetirement, endAge, stress chips. CPF inside SV. | D13: Year-by-year wealth path. GP does not run the year step. | E13: preWealth = session without the plan; postWealth = plus included planMth / planLump / planSum / planPrem. svNumSims defaults to 20. Investment contribution = max(0, take-home − expenseMonthly) once a year. This workbook does not project the path. | F13: src/sv_payload.py → POST /v1/project → SV | G13: Assumptions (stress catalogue) | H13: POST /v1/project
A14: Journey order (one session, each step adds attributes)
A15: Shared inputs (Assumptions · CPF · Need parameters · Risk · Stress events) → About you → CPF (on for Singapore only) → People Like You (or the customer edits the same money fields) → Need Profiler → Need Calculator → HappiU (no plan) → Plan Calculator → Budget Calculator → Scenario Visualizer → HappiU (with plan). Workbook-only: FX (local → USD) then Validation (USD rules).
A17: UNIFIED types in code order: N_INC, N_CRI, N_TPD, N_HOS (protection) · N_RET, N_EDU, N_SAV, N_PRP (wealth). Goal-card sliders live on the Need Calculator tab. Discrepancies lists remaining multi-country / multi-currency work.

Sheet Selected persona
A1: Selected persona — pick one id here. Every calculation tab follows this cell.
A2: Selected persona | B2: P03 | C2: =IFERROR(INDEX(Personas!B$3:B$52,MATCH($B$2,Personas!$A$3:$A$52,0)),"") -> Daniel Koh | D2: This is the only picker. CPF, People Like You, Need Profiler, Need Calculator, Plan, Budget, FX, and Validation follow this cell. | F2: A · INPUT DATA
A3: Attribute | B3: Value | C3: Kind | D3: Source / formula | F3: B · LLM PREDICTED DATA
A4: A · ABOUT YOU — from the Personas row (edit there) | F4: C · DETERMINISTICALLY CALCULATED
A5: name | B5: =IFERROR(INDEX(Personas!B$3:B$52,MATCH($B$2,Personas!$A$3:$A$52,0)),"") -> Daniel Koh | C5: A · input | D5: Personas B. | F5: D · ASSUMPTIONS / SHARED DATA
A6: age | B6: =IFERROR(INDEX(Personas!C$3:C$52,MATCH($B$2,Personas!$A$3:$A$52,0)),"") -> 34 | C6: A · input | D6: Personas C. | F6: E · USER / FRONTEND OVERRIDE
A7: gender | B7: =IFERROR(INDEX(Personas!D$3:D$52,MATCH($B$2,Personas!$A$3:$A$52,0)),"") -> Female | C7: A · input | D7: Personas D.
A8: residency | B8: =IFERROR(INDEX(Personas!E$3:E$52,MATCH($B$2,Personas!$A$3:$A$52,0)),"") -> Citizen | C8: A · input | D8: Personas E.
A9: country | B9: =IFERROR(INDEX(Personas!F$3:F$52,MATCH($B$2,Personas!$A$3:$A$52,0)),"") -> Singapore | C9: A · input | D9: Personas F. CPF on/off uses this.
A10: occupation | B10: =IFERROR(INDEX(Personas!G$3:G$52,MATCH($B$2,Personas!$A$3:$A$52,0)),"") -> Accountant | C10: A · input | D10: Personas G. Income clamp band.
A11: dependents | B11: =IFERROR(INDEX(Personas!H$3:H$52,MATCH($B$2,Personas!$A$3:$A$52,0)),"") -> 1 | C11: A · input | D11: Personas H.
A12: maritalStatus | B12: =IFERROR(INDEX(Personas!I$3:I$52,MATCH($B$2,Personas!$A$3:$A$52,0)),"") -> 0 | C12: A · input | D12: Personas I. Blank = infer on People Like You.
A13: what this row varies | B13: =IFERROR(INDEX(Personas!AD$3:AD$52,MATCH($B$2,Personas!$A$3:$A$52,0)),"") -> Accountant; age 34; Citizen; 1 dep; home; non-smoker | C13: A · input | D13: Personas AD. Why this persona exists.
A15: B · LLM PREDICTED — from the Personas row (edit there)
A16: incomeMonthly (LLM) | B16: =IFERROR(INDEX(Personas!J$3:J$52,MATCH($B$2,Personas!$A$3:$A$52,0)),"") -> 7140 | C16: B · LLM predicted | D16: Personas J. Before clamp and CPF.
A17: currency | B17: USD | C17: B · LLM predicted | D17: Personas K. FX looks this up.
A18: risk ability | B18: =IFERROR(INDEX(Personas!L$3:L$52,MATCH($B$2,Personas!$A$3:$A$52,0)),"") -> moderate | C18: B · LLM predicted | D18: Personas L.
A19: price sensitivity | B19: =IFERROR(INDEX(Personas!M$3:M$52,MATCH($B$2,Personas!$A$3:$A$52,0)),"") -> medium | C19: B · LLM predicted | D19: Personas M.
A20: owns property | B20: =IFERROR(INDEX(Personas!N$3:N$52,MATCH($B$2,Personas!$A$3:$A$52,0)),"") -> TRUE | C20: B · LLM predicted | D20: Personas N.
A21: owns car | B21: =IFERROR(INDEX(Personas!O$3:O$52,MATCH($B$2,Personas!$A$3:$A$52,0)),"") -> TRUE | C21: B · LLM predicted | D21: Personas O.
A22: is smoker | B22: =IFERROR(INDEX(Personas!U$3:U$52,MATCH($B$2,Personas!$A$3:$A$52,0)),"") -> FALSE | C22: B · LLM predicted | D22: Personas U.
A23: life expectancy | B23: =IFERROR(INDEX(Personas!V$3:V$52,MATCH($B$2,Personas!$A$3:$A$52,0)),"") -> 88 | C23: B · LLM predicted | D23: Personas V.
A24: retirement lifestyle | B24: =IFERROR(INDEX(Personas!T$3:T$52,MATCH($B$2,Personas!$A$3:$A$52,0)),"") -> Comfortable | C24: B · LLM predicted | D24: Personas T.
A26: C · EFFECTIVE SESSION — after CPF, People Like You, and Money-page overrides
A27: CPF on | B27: =CPF_on -> TRUE | C27: C · calculated | D27: From the CPF tab.
A28: incomeMonthly | B28: =PLU_incomeMonthly -> 7140 | C28: C · calculated | D28: Clamped LLM income.
A29: take-home | B29: =PLU_takeHome -> 5712 | C29: C · calculated | D29: Gross minus employee CPF when CPF is on.
A30: expenseMonthly | B30: =PLU_expenseMonthly -> 4141.2 | C30: C · calculated | D30: Override if Personas W is set.
A31: cash | B31: =PLU_cash -> 18378 | C31: C · calculated | D31: Cash & Savings.
A32: investments | B32: =PLU_investments -> 104144 | C32: C · calculated
A33: property | B33: =PLU_property -> 350000 | C33: C · calculated | D33: 0 if renter.
A34: mortgage | B34: =PLU_mortgage -> 192500 | C34: C · calculated
A35: PLU liabilities | B35: =PLU_liabilities -> 85765.68 | C35: C · calculated | D35: Not the mortgage.
A36: life sum assured | B36: =PLU_lifeSum -> 428400 | C36: C · calculated

Sheet Personas
A1: A · INPUT DATA — About you (typed / session) | J1: B · LLM PREDICTED DATA — 13 fields from people_like_you_all_fields.json | W1: E · USER / FRONTEND OVERRIDE — Money page (blank = keep People Like You calculated) | AD1: notes | AF1: A · INPUT DATA
A2: id | B2: name | C2: age | D2: gender | E2: residency | F2: country | G2: occupation | H2: dependents | I2: maritalStatus (blank = infer) | J2: income | K2: currency | L2: risk_ability | M2: price_sensitivity | N2: property | O2: car | P2: ward_type | Q2: hospitalization_type | R2: travelling | S2: sports | T2: retirement_lifestyle | U2: is_smoker | V2: life_expectancy | W2: expenseMonthly | X2: cash (Cash & Savings) | Y2: investments | Z2: property value | AA2: mortgage (loans) | AB2: PLU liabilities | AC2: life sum assured | AD2: What this row varies | AF2: B · LLM PREDICTED DATA
A3: P01 | B3: Aisha Rahman | C3: 22 | D3: Female | E3: Citizen | F3: Singapore | G3: Nurse | H3: 0 | J3: 4200 | K3: SGD | L3: conservative | M3: high | N3: FALSE | O3: FALSE | P3: Ward | Q3: Public | R3: FALSE | S3: Yoga | T3: Basic | U3: FALSE | V3: 86 | W3: 2268 | X3: 983 | Y3: 5569 | Z3: 0 | AA3: 0 | AB3: 4586.4 | AC3: 0 | AD3: Nurse; age 22; Citizen; 0 dep; rent; non-smoker | AF3: C · DETERMINISTICALLY CALCULATED
A4: P02 | B4: Wei Ling Tan | C4: 27 | D4: Male | E4: PR | F4: Singapore | G4: Teacher | H4: 0 | J4: 6020 | K4: SGD | L4: moderate | M4: medium | N4: FALSE | O4: TRUE | P4: Double | Q4: Private | R4: TRUE | S4: Running | T4: Comfortable | U4: FALSE | V4: 81 | W4: 3250.8 | X4: 8452 | Y4: 47895 | Z4: 0 | AA4: 0 | AB4: 39443.04 | AC4: 0 | AD4: Teacher; age 27; PR; 0 dep; rent; non-smoker | AF4: D · ASSUMPTIONS / SHARED DATA
A5: P03 | B5: Daniel Koh | C5: 34 | D5: Female | E5: Citizen | F5: Singapore | G5: Accountant | H5: 1 | J5: 7140 | K5: SGD | L5: moderate | M5: medium | N5: TRUE | O5: TRUE | P5: Single | Q5: Private | R5: TRUE | S5: Swimming | T5: Comfortable | U5: FALSE | V5: 88 | W5: 4141.2 | X5: 18378 | Y5: 104144 | Z5: 350000 | AA5: 192500 | AB5: 85765.68 | AC5: 428400 | AD5: Accountant; age 34; Citizen; 1 dep; home; non-smoker | AF5: E · USER / FRONTEND OVERRIDE
A6: P04 | B6: Priya Nair | C6: 41 | D6: Male | E6: Citizen | F6: Singapore | G6: Marketing Manager | H6: 2 | J6: 4550 | K6: SGD | L6: conservative | M6: high | N6: TRUE | O6: TRUE | P6: Ward | Q6: Public | R6: FALSE | S6: I dont do sports | T6: frugal | U6: TRUE | V6: 78 | W6: 2821 | X6: 14742 | Y6: 83538 | Z6: 350000 | AA6: 192500 | AB6: 68796 | AC6: 273000 | AD6: Marketing Manager; age 41; Citizen; 2 dep; home; smoker
A7: P05 | B7: Marcus Lim | C7: 47 | D7: Female | E7: Foreigner | F7: Singapore | G7: Software Engineer | H7: 2 | J7: 5000 | K7: SGD | L7: aggressive | M7: high | N7: TRUE | O7: FALSE | P7: A | Q7: Private | R7: TRUE | S7: Adventurous Sports | T7: only the best | U7: FALSE | V7: 90 | W7: 3875 | X7: 26325 | Y7: 149175 | Z7: 350000 | AA7: 192500 | AB7: 122850 | AC7: 300000 | AD7: Software Engineer; age 47; Foreigner; 2 dep; home; non-smoker
A8: P06 | B8: Hannah Wong | C8: 32 | D8: Male | E8: Citizen | F8: Singapore | G8: Doctor | H8: 1 | J8: 13910 | K8: SGD | L8: moderate | M8: medium | N8: TRUE | O8: TRUE | P8: B | Q8: Public | R8: TRUE | S8: Life style activities | T8: stress-free | U8: FALSE | V8: 83 | W8: 8924.75 | X8: 33514 | Y8: 189913 | Z8: 650000 | AA8: 357500 | AB8: 156398.55 | AC8: 834600 | AD8: Doctor; age 32; Citizen; 1 dep; home; non-smoker
A9: P07 | B9: Julian Chee | C9: 54 | D9: Female | E9: PR | F9: Singapore | G9: Investment Banker | H9: 0 | J9: 5525 | K9: SGD | L9: conservative | M9: high | N9: TRUE | O9: TRUE | P9: Single | Q9: Private | R9: FALSE | S9: Walking | T9: Basic | U9: FALSE | V9: 89 | W9: 2983.5 | X9: 42664 | Y9: 241763 | Z9: 350000 | AA9: 192500 | AB9: 199098.9 | AC9: 200000 | AD9: Investment Banker; age 54; PR; 0 dep; home; non-smoker
A10: P08 | B10: Mei Fen Ong | C10: 60 | D10: Male | E10: Citizen | F10: Singapore | G10: CEO | H10: 3 | J10: 5975 | K10: SGD | L10: conservative | M10: high | N10: TRUE | O10: TRUE | P10: Ward | Q10: Public | R10: FALSE | S10: I dont do sports | T10: frugal | U10: TRUE | V10: 76 | W10: 4042.5 | X10: 30098 | Y10: 170557 | Z10: 350000 | AA10: 192500 | AB10: 140458.5 | AC10: 358500 | AD10: CEO; age 60; Citizen; 3 dep; home; smoker
A11: P09 | B11: Hafiz Abdullah | C11: 25 | D11: Female | E11: Citizen | F11: Singapore | G11: Baker | H11: 0 | J11: 3350 | K11: SGD | L11: moderate | M11: high | N11: FALSE | O11: FALSE | P11: Ward | Q11: Public | R11: TRUE | S11: HIIT | T11: Comfortable | U11: FALSE | V11: 87 | W11: 1809 | X11: 3136 | Y11: 17768 | Z11: 0 | AA11: 0 | AB11: 14632.8 | AC11: 0 | AD11: Baker; age 25; Citizen; 0 dep; rent; non-smoker
A12: P10 | B12: Siti Hassan | C12: 37 | D12: Male | E12: Foreigner | F12: Singapore | G12: Driver | H12: 2 | J12: 4250 | K12: SGD | L12: aggressive | M12: high | N12: FALSE | O12: TRUE | P12: Double | Q12: Private | R12: TRUE | S12: Football | T12: Luxurious | U12: FALSE | V12: 80 | W12: 3293.75 | X12: 13770 | Y12: 78030 | Z12: 0 | AA12: 0 | AB12: 64260 | AC12: 255000 | AD12: Driver; age 37; Foreigner; 2 dep; rent; non-smoker
A13: P11 | B13: Aisha Ng | C13: 51 | D13: Female | E13: Citizen | F13: Singapore | G13: Nurse | H13: 1 | J13: 7140 | K13: SGD | L13: moderate | M13: medium | N13: TRUE | O13: TRUE | P13: A | Q13: Private | R13: TRUE | S13: Pilates | T13: only the best | U13: FALSE | V13: 91 | W13: 4141.2 | X13: 42412 | Y13: 240332 | Z13: 350000 | AA13: 192500 | AB13: 197920.8 | AC13: 428400 | AD13: Nurse; age 51; Citizen; 1 dep; home; non-smoker
A14: P12 | B14: Wei Ling Chua | C14: 66 | D14: Male | E14: Citizen | F14: Singapore | G14: Teacher | H14: 0 | J14: 9800 | K14: SGD | L14: conservative | M14: medium | N14: TRUE | O14: FALSE | P14: Ward | Q14: Public | R14: FALSE | S14: I dont do sports | T14: Basic | U14: FALSE | V14: 85 | W14: 6210 | X14: 121095 | Y14: 686205 | Z14: 350000 | AA14: 192500 | AB14: 565110 | AC14: 200000 | AD14: Teacher; age 66; Citizen; 0 dep; home; non-smoker
A15: P13 | B15: Daniel Lee | C15: 30 | D15: Female | E15: PR | F15: Singapore | G15: Accountant | H15: 1 | J15: 6580 | K15: SGD | L15: moderate | M15: medium | N15: FALSE | O15: TRUE | P15: Double | Q15: Public | R15: FALSE | S15: Running | T15: Comfortable | U15: TRUE | V15: 79 | W15: 3816.4 | X15: 11726 | Y15: 66445 | Z15: 0 | AA15: 0 | AB15: 54719.28 | AC15: 394800 | AD15: Accountant; age 30; PR; 1 dep; rent; smoker
A16: P14 | B16: Priya Goh | C16: 44 | D16: Male | E16: Citizen | F16: Singapore | G16: Marketing Manager | H16: 4 | J16: 4775 | K16: SGD | L16: aggressive | M16: high | N16: TRUE | O16: TRUE | P16: Single | Q16: Private | R16: TRUE | S16: Golf | T16: Luxurious | U16: FALSE | V16: 84 | W16: 3342.5 | X16: 9884 | Y16: 56011 | Z16: 350000 | AA16: 192500 | AB16: 46126.5 | AC16: 286500 | AD16: Marketing Manager; age 44; Citizen; 4 dep; home; non-smoker
A17: P15 | B17: Marcus Teo | C17: 57 | D17: Female | E17: Citizen | F17: Singapore | G17: Software Engineer | H17: 2 | J17: 5750 | K17: SGD | L17: conservative | M17: high | N17: TRUE | O17: TRUE | P17: B | Q17: Private | R17: FALSE | S17: Life style activities | T17: stress-free | U17: FALSE | V17: 92 | W17: 3654.12 | X17: 34373 | Y17: 194778 | Z17: 350000 | AA17: 192500 | AB17: 160405.06 | AC17: 345000 | AD17: Software Engineer; age 57; Citizen; 2 dep; home; non-smoker
... A52: P50 | B52: Siti Lim | C52: 47 | D52: Female | E52: Foreigner | F52: Singapore | G52: Driver | H52: 2 | J52: 5000 | K52: SGD | L52: aggressive | M52: high | N52: TRUE | O52: FALSE | P52: A | Q52: Private | R52: TRUE | S52: Adventurous Sports | T52: only the best | U52: FALSE | V52: 90 | W52: 3875 | X52: 26325 | Y52: 149175 | Z52: 350000 | AA52: 192500 | AB52: 122850 | AC52: 300000 | AD52: Driver; age 47; Foreigner; 2 dep; home; non-smoker

Sheet CPF
A1: CPF — social-security plug-in. In: gross, age, residency, country. Out: employee contribution, take-home. Runs in user currency.
A2: Selected persona | B2: =SelectedPersona -> P03 | C2: =IFERROR(INDEX(Personas!B$3:B$52,MATCH($B$2,Personas!$A$3:$A$52,0)),"") -> Daniel Koh | D2: Follows the dropdown on the Selected persona tab. | F2: A · INPUT DATA
A3: Attribute | B3: Value | C3: Kind | D3: Source / formula | F3: B · LLM PREDICTED DATA
A4: A · INPUT DATA — from the selected Personas row | F4: C · DETERMINISTICALLY CALCULATED | I4: D · MODULE PER COUNTRY — TRUE = SG-CPF module; FALSE = default module (no contribution)
A5: country | B5: =IFERROR(INDEX(Personas!F$3:F$52,MATCH($B$2,Personas!$A$3:$A$52,0)),"") -> Singapore | C5: A · input | D5: Personas F. Looks up the country switch. | F5: D · ASSUMPTIONS / SHARED DATA | I5: country | J5: CPF on? | K5: note
A6: residency | B6: =IFERROR(INDEX(Personas!E$3:E$52,MATCH($B$2,Personas!$A$3:$A$52,0)),"") -> Citizen | C6: A · input | D6: Personas E. When CPF is on, Foreigner → rate 0. | F6: E · USER / FRONTEND OVERRIDE | I6: Singapore | J6: TRUE | K6: src/cpf.py applies. Citizen / PR contribute; Foreigner rate 0.
A7: age | B7: =IFERROR(INDEX(Personas!C$3:C$52,MATCH($B$2,Personas!$A$3:$A$52,0)),"") -> 34 | C7: A · input | D7: Personas C. Age-band rate when CPF is on. | I7: Vietnam | J7: FALSE | K7: No CPF. Take-home = gross.
A8: incomeMonthly | B8: =IFERROR(INDEX(Personas!J$3:J$52,MATCH($B$2,Personas!$A$3:$A$52,0)),"") -> 7140 | C8: A · input | D8: Personas J (LLM or user overwrite). | I8: Malaysia | J8: FALSE | K8: No CPF. Take-home = gross.
I9: Thailand | J9: FALSE | K9: No CPF. Take-home = gross.
A10: D · ASSUMPTIONS — src/cpf.py (used only when CPF is on) | I10: Philippines | J10: FALSE | K10: No CPF. Take-home = gross.
A11: OW_CEILING | B11: 8000 | C11: D · assumption / shared | D11: Ordinary-wage ceiling. Employee CPF is on min(gross, this). | I11: Australia | J11: FALSE | K11: No CPF. Take-home = gross.
A12: cpfRate_to55 | B12: 0.2 | C12: D · assumption / shared | D12: Employee rate age ≤ 55. | I12: Germany | J12: FALSE | K12: No CPF. Take-home = gross.
A13: cpfRate_to60 | B13: 0.18 | C13: D · assumption / shared | D13: Age 56–60. | I13: Hong Kong | J13: FALSE | K13: No CPF. Take-home = gross.
A14: cpfRate_to65 | B14: 0.125 | C14: D · assumption / shared | D14: Age 61–65. | I14: United States | J14: FALSE | K14: No CPF. Take-home = gross.
A15: cpfRate_to70 | B15: 0.075 | C15: D · assumption / shared | D15: Age 66–70.
A16: cpfRate_over70 | B16: 0.05 | C16: D · assumption / shared | D16: Age > 70.
A18: E · OVERRIDE — blank = country switch. TRUE / FALSE forces CPF on or off
A19: CPF on? (override) | C19: E · user / frontend override | D19: TRUE / FALSE / blank. Blank uses the country table.
A21: C · DETERMINISTICALLY CALCULATED — src/cpf.py when on; identity when off
A22: CPF on (effective) | B22: =IF(B19="",IFERROR(VLOOKUP(B5,CpfCountrySwitch,2,FALSE),FALSE),B19) -> TRUE | C22: C · calculated | D22: Country table, unless the orange override is set.
A23: module used | B23: =IF(B22=TRUE,"SG-CPF (src/cpf.py)","default: no contribution, take-home = gross") -> SG-CPF (src/cpf.py) | C23: C · calculated | D23: Plug-in interface. Other countries get their own module later; the rest of the model does not change.
A24: Singapore age-band rate | B24: =IF(LOWER(B6)="foreigner",0,IF(B7<=55,cpfRate_to55,IF(B7<=60,cpfRate_to60,IF(B7<=65,cpfRate_to65,IF(B7<=70,cpfRate_to70,cpfRate_over70))))) -> 0.2 | C24: C · calculated | D24: employee_cpf_rate. Ignored when CPF is off.
A25: CPF rate used | B25: =IF(B22=TRUE,B24,0) -> 0.2 | C25: C · calculated | D25: 0 when CPF is off for this country.
A26: employee CPF | B26: =IF(OR(B22<>TRUE,B8<=0,B25<=0),0,FLOOR(MIN(B8,OW_CEILING)*B25,1)) -> 1428 | C26: C · calculated | D26: floor(min(gross, ceiling) × rate). 0 if CPF off.
A27: take-home | B27: =IF(B8<=0,0,ROUND(MAX(0,B8-B26),2)) -> 5712 | C27: C · calculated | D27: Gross minus employee CPF. Equals income when CPF is off.

Sheet People Like You
A1: People Like You — selected persona. Spend, assets, home, life cover. Take-home comes from the CPF tab.
A2: Selected persona | B2: =SelectedPersona -> P03 | C2: =IFERROR(INDEX(Personas!B$3:B$52,MATCH($B$2,Personas!$A$3:$A$52,0)),"") -> Daniel Koh | D2: Follows the dropdown on the Selected persona tab. | F2: A · INPUT DATA
A3: Attribute | B3: Value | C3: Kind | D3: Source / formula | F3: B · LLM PREDICTED DATA
A4: A · INPUT DATA — About you from the selected Personas row | F4: C · DETERMINISTICALLY CALCULATED
A5: age | B5: =IFERROR(INDEX(Personas!C$3:C$52,MATCH($B$2,Personas!$A$3:$A$52,0)),"") -> 34 | C5: A · input | D5: Personas C. Working years = age − 21. | F5: D · ASSUMPTIONS / SHARED DATA
A6: gender | B6: =IFERROR(INDEX(Personas!D$3:D$52,MATCH($B$2,Personas!$A$3:$A$52,0)),"") -> Female | C6: A · input | D6: Personas D. Not used by this component. | F6: E · USER / FRONTEND OVERRIDE
A7: residency | B7: =IFERROR(INDEX(Personas!E$3:E$52,MATCH($B$2,Personas!$A$3:$A$52,0)),"") -> Citizen | C7: A · input | D7: Personas E. Passed to the CPF tab (Foreigner → 0 when CPF is on).
A8: country | B8: =IFERROR(INDEX(Personas!F$3:F$52,MATCH($B$2,Personas!$A$3:$A$52,0)),"") -> Singapore | C8: A · input | D8: Personas F. CPF on/off is decided on the CPF tab.
A9: occupation | B9: =IFERROR(INDEX(Personas!G$3:G$52,MATCH($B$2,Personas!$A$3:$A$52,0)),"") -> Accountant | C9: A · input | D9: Personas G. Looks up income_anchors.json Singapore band.
A10: dependents | B10: =IFERROR(INDEX(Personas!H$3:H$52,MATCH($B$2,Personas!$A$3:$A$52,0)),"") -> 1 | C10: A · input | D10: Personas H. Spend-share +5 pp each; 5× income life cover if > 0.
A11: maritalStatus (typed) | B11: =IFERROR(INDEX(Personas!I$3:I$52,MATCH($B$2,Personas!$A$3:$A$52,0)),"") -> 0 | C11: A · input | D11: Personas I. Blank → infer below.
A13: B · LLM PREDICTED DATA — fields this component reads from Personas
A14: income (LLM gross monthly) | B14: =IFERROR(INDEX(Personas!J$3:J$52,MATCH($B$2,Personas!$A$3:$A$52,0)),"") -> 7140 | C14: B · LLM predicted | D14: Personas J. people_like_you_all_fields.json income.
A15: currency | B15: =IFERROR(INDEX(Personas!K$3:K$52,MATCH($B$2,Personas!$A$3:$A$52,0)),"") -> SGD | C15: B · LLM predicted | D15: Personas K. SGD in this workbook.
A16: property (owns home) | B16: =IFERROR(INDEX(Personas!N$3:N$52,MATCH($B$2,Personas!$A$3:$A$52,0)),"") -> TRUE | C16: B · LLM predicted | D16: Personas N. seed_property_value if TRUE.
A17: life_expectancy (raw) | B17: =IFERROR(INDEX(Personas!V$3:V$52,MATCH($B$2,Personas!$A$3:$A$52,0)),"") -> 88 | C17: B · LLM predicted | D17: Personas V. Capped at 99. Missing or ≤ 0 → 85.
A19: D · ASSUMPTIONS / SHARED DATA — named cells on Assumptions (CPF is on the CPF tab)
A20: spendShareBase | B20: =spendShareBase -> 0.675 | C20: D · assumption / shared | D20: 67.5% of take-home.
A21: spendSharePerDependant | B21: =spendSharePerDependant -> 0.05 | C21: D · assumption / shared | D21: +5 pp per dependant.
A22: spendShareCap | B22: =spendShareCap -> 0.9 | C22: D · assumption / shared | D22: 90% cap.
A23: assetsSaveShare | B23: =assetsSaveShare -> 0.5 | C23: D · assumption / shared | D23: 50% of annual surplus saved.
A24: workStartAge | B24: =workStartAge -> 21 | C24: D · assumption / shared | D24: 21. Working years = max(0, age − 21).
A25: CASH_SAVINGS_SHARE | B25: =CASH_SAVINGS_SHARE -> 0.15 | C25: D · assumption / shared | D25: src/predict.py 15% cash.
A26: INVESTMENTS_SHARE | B26: =INVESTMENTS_SHARE -> 0.85 | C26: D · assumption / shared | D26: src/predict.py 85%.
A27: liabilityRatio | B27: =liabilityRatio -> 0.7 | C27: D · assumption / shared | D27: PLU liabilities = liquid assets × 0.7 (not the mortgage).
A28: propertyLow (USD) | B28: =propertyLow -> 259000 | C28: D · assumption / shared | D28: income < propertyIncomeLow (USD).
A29: propertyMid (USD) | B29: =propertyMid -> 481000 | C29: D · assumption / shared | D29: income between the two USD bands.
A30: propertyHigh (USD) | B30: =propertyHigh -> 629000 | C30: D · assumption / shared | D30: income > propertyIncomeHigh (USD).
A31: propertyIncomeLow (USD) | B31: =propertyIncomeLow -> 7400 | C31: D · assumption / shared | D31: Monthly gross income in USD.
A32: propertyIncomeHigh (USD) | B32: =propertyIncomeHigh -> 14800 | C32: D · assumption / shared | D32: Monthly gross income in USD.
A33: PROPERTY_LTV | B33: =PROPERTY_LTV -> 0.55 | C33: D · assumption / shared | D33: Mortgage = round(property × 55%).
A34: lifePremiumRate | B34: =lifePremiumRate -> 0.0031 | C34: D · assumption / shared | D34: 0.31% of sum assured.
A35: life cover step (user currency) | B35: =FX_lifeRound -> 100000 | C35: D · assumption / shared | D35: lifeRoundUnit (USD) as a nice step in user currency (FX tab).
A36: lifeExpectancyDefault | B36: =lifeExpectancyDefault -> 85 | C36: D · assumption / shared | D36: Used when raw LE is missing or ≤ 0.
A38: C · DETERMINISTICALLY CALCULATED — _apply_plu. Take-home is read from the CPF tab.
A39: band min | B39: =IFERROR(INDEX(Assumptions!$F$6:$F$13,MATCH(B9,Assumptions!$E$6:$E$13,0)),"") -> 5600 | C39: C · calculated | D39: income_anchors.json Singapore min for occupation.
A40: band max | B40: =IFERROR(INDEX(Assumptions!$G$6:$G$13,MATCH(B9,Assumptions!$E$6:$E$13,0)),"") -> 11200 | C40: C · calculated | D40: income_anchors.json Singapore max.
A41: incomeMonthly (clamped) | B41: =IF(OR(B39="",B14=0),B14,MIN(MAX(B14,B39),B40)) -> 7140 | C41: C · calculated | D41: Clamp LLM income into the occupation band. 0 stays 0.
A42: CPF on (from CPF tab) | B42: =CPF_on -> TRUE | C42: A · input | D42: Country switch or orange override on the CPF tab.
A43: CPF rate | B43: =CPF_rate -> 0.2 | C43: C · calculated | D43: 0 when CPF is off for this country.
...

Sheet Need Profiler
A1: Need Profiler — selected persona. Weighted scores → two protection + two growth. Orange Enable? overrides.
A2: Selected persona | B2: =SelectedPersona -> P03 | C2: =IFERROR(INDEX(Personas!B$3:B$52,MATCH($B$2,Personas!$A$3:$A$52,0)),"") -> Daniel Koh | D2: Follows the dropdown on the Selected persona tab. | F2: A · INPUT DATA
A3: Attribute | B3: Value | C3: Kind | D3: Source / formula | F3: B · LLM PREDICTED DATA
A4: A · INPUT DATA — from selected Personas + People Like You results | F4: C · DETERMINISTICALLY CALCULATED
A5: age | B5: =IFERROR(INDEX(Personas!C$3:C$52,MATCH($B$2,Personas!$A$3:$A$52,0)),"") -> 34 | C5: A · input | D5: Personas C. Bucket <21 / ≤30 / ≤40 / else. | F5: D · ASSUMPTIONS / SHARED DATA
A6: gender | B6: =IFERROR(INDEX(Personas!D$3:D$52,MATCH($B$2,Personas!$A$3:$A$52,0)),"") -> Female | C6: A · input | D6: Personas D. male=3, female=2. | F6: E · USER / FRONTEND OVERRIDE
A7: dependents | B7: =IFERROR(INDEX(Personas!H$3:H$52,MATCH($B$2,Personas!$A$3:$A$52,0)),"") -> 1 | C7: A · input | D7: Personas H. 0 / 1 / ≥2 → 0 / 2 / 4.
A8: occupation | B8: =IFERROR(INDEX(Personas!G$3:G$52,MATCH($B$2,Personas!$A$3:$A$52,0)),"") -> Accountant | C8: A · input | D8: Personas G. Self-employed tokens → 2, else 1.
A9: incomeMonthly (from PLU) | B9: =PLU_incomeMonthly -> 7140 | C9: A · input | D9: People Like You calculated income, used as profiler Income.
A10: expenseMonthly (from PLU) | B10: =PLU_expenseMonthly -> 4141.2 | C10: A · input | D10: People Like You calculated spend.
A11: liquid assets (from PLU) | B11: =PLU_cash+PLU_investments -> 122522 | C11: A · input | D11: cash + investments.
A12: PLU liabilities (from PLU) | B12: =PLU_liabilities -> 85765.68 | C12: A · input | D12: Not the mortgage.
A14: B · LLM PREDICTED DATA — lifestyle flags this component reads
A15: is_smoker | B15: =IFERROR(INDEX(Personas!U$3:U$52,MATCH($B$2,Personas!$A$3:$A$52,0)),"") -> FALSE | C15: B · LLM predicted | D15: Personas U. TRUE→3, else 1 (JSON has no Smoking options).
A16: hospitalization_type | B16: =IFERROR(INDEX(Personas!Q$3:Q$52,MATCH($B$2,Personas!$A$3:$A$52,0)),"") -> Private | C16: B · LLM predicted | D16: Personas Q. private=4, public=2.
A17: ward_type | B17: =IFERROR(INDEX(Personas!P$3:P$52,MATCH($B$2,Personas!$A$3:$A$52,0)),"") -> Single | C17: B · LLM predicted | D17: Personas P. A=3, B=2. Single/Double/Ward score 0.
A18: retirement_lifestyle | B18: =IFERROR(INDEX(Personas!T$3:T$52,MATCH($B$2,Personas!$A$3:$A$52,0)),"") -> Comfortable | C18: B · LLM predicted | D18: Personas T. frugal / stress-free / only the best.
A19: sports | B19: =IFERROR(INDEX(Personas!S$3:S$52,MATCH($B$2,Personas!$A$3:$A$52,0)),"") -> Swimming | C19: B · LLM predicted | D19: Personas S. Adventurous / I dont do sports / Life style.
A20: property (owns home) | B20: =IFERROR(INDEX(Personas!N$3:N$52,MATCH($B$2,Personas!$A$3:$A$52,0)),"") -> TRUE | C20: B · LLM predicted | D20: Personas N. Swaps N_SAV ↔ N_PRP in the second growth slot.
A22: D · ASSUMPTIONS / SHARED DATA — used by this component
A23: Existing hospital cover | B23: 0 | C23: D · assumption / shared | D23: build_profiler_profile hard-codes Existing*Coverage = False → option weight 1.
A24: Existing disability cover | B24: 0 | C24: D · assumption / shared | D24: Same. Stored as 0 here; option weight of False is 1.
A25: USD per 1 local | B25: =FX_usdPerLocal -> 0.74 | C25: D · assumption / shared | D25: From the FX tab. Income / expense / assets / liabilities convert local × this rate.
A26: Selection rule | B26: 2 prot + N_RET + 1 growth | C26: D · assumption / shared | D26: select_unified_top ignores top_n. If owns home, N_PRP replaces N_SAV.
A27: Profiler weight matrix | B27: Assumptions!B90:M104 | C27: D · assumption / shared | D27: Need_profiler.json needs_factor_weights. SUMPRODUCT with option weights.
A29: C · DETERMINISTICALLY CALCULATED — local × FX → USD, then 15 option weights
A30: usd Income | B30: =IF(FX_usdPerLocal="","",PLU_incomeMonthly*FX_usdPerLocal) -> 5283.6 | C30: C · calculated | D30: local income × FX. S$5,000 × 0.74 ≈ 3,700 USD → Income weight 2.
A31: usd Expense | B31: =IF(FX_usdPerLocal="","",PLU_expenseMonthly*FX_usdPerLocal) -> 3064.488 | C31: C · calculated | D31: local expense × FX.
A32: usd Assets | B32: =IF(FX_usdPerLocal="","",(PLU_cash+PLU_investments)*FX_usdPerLocal) -> 90666.28 | C32: C · calculated | D32: cash + investments × FX.
A33: usd Liab | B33: =IF(FX_usdPerLocal="","",PLU_liabilities*FX_usdPerLocal) -> 63466.603 | C33: C · calculated | D33: PLU liabilities × FX.
A34: ow Age | B34: =IF(B5<21,1,IF(B5<=30,2,IF(B5<=40,3,4))) -> 3 | C34: C · calculated | D34: _get_option_weight Date of Birth.
A35: ow Gender | B35: =IF(LOWER(B6)="male",3,IF(LOWER(B6)="female",2,0)) -> 2 | C35: C · calculated | D35: male=3, female=2.
A36: ow Deps | B36: =IF(B7=0,0,IF(B7=1,2,4)) -> 2 | C36: C · calculated | D36: 0 / 1 / else.
A37: ow Occ | B37: =IF(OR(ISNUMBER(SEARCH("self",B8)),ISNUMBER(SEARCH("entrepreneur",B8)),ISNUMBER(SEARCH("own business",B8)),ISNUMBER(SEARCH("freelance",B8))),2,1) -> 1 | C37: C · calculated | D37: Self-employed tokens.
A38: ow Smoke | B38: =IF(B15=TRUE,3,1) -> 1 | C38: C · calculated | D38: No Smoking options in JSON.
A39: ow Income | B39: =IF(B30<1000,4,IF(B30<2500,3,IF(B30<5000,2,IF(B30<10000,1,0)))) -> 1 | C39: C · calculated | D39: Need_profiler.json Income lt bands (USD after FX).
A40: ow Expense | B40: =IF(B31<600,4,IF(B31<1500,3,IF(B31<3000,2,IF(B31<6000,1,0)))) -> 1 | C40: C · calculated | D40: Expense USD bands (~0.6× income).
A41: ow Assets | B41: =IF(B32<10000,4,IF(B32<50000,3,IF(B32<150000,2,IF(B32<500000,1,0)))) -> 2 | C41: C · calculated | D41: Assets USD bands (stock).
A42: ow Liab | B42: =IF(B33<5000,4,IF(B33<25000,3,IF(B33<100000,2,IF(B33<250000,1,0)))) -> 2 | C42: C · calculated | D42: Liabilities USD bands (stock).
A43: ow HospExist | B43: 1 | C43: C · calculated | D43: Existing hospital coverage always False → 1.
...

Sheet Need Calculator
A1: Need Calculator — selected persona. Runs in USD (S-block), results back in user currency. Orange cells are goal-card sliders (user currency).
A2: Selected persona | B2: =SelectedPersona -> P03 | C2: =IFERROR(INDEX(Personas!B$3:B$52,MATCH($B$2,Personas!$A$3:$A$52,0)),"") -> Daniel Koh | D2: Follows the dropdown on the Selected persona tab. | F2: A · INPUT DATA
A3: Attribute | B3: Value | C3: Kind | D3: Source / formula | F3: B · LLM PREDICTED DATA
A4: A · INPUT DATA — from Personas, People Like You, and Need Profiler | F4: C · DETERMINISTICALLY CALCULATED
A5: age | B5: =IFERROR(INDEX(Personas!C$3:C$52,MATCH($B$2,Personas!$A$3:$A$52,0)),"") -> 34 | C5: A · input | D5: Personas C. | F5: D · ASSUMPTIONS / SHARED DATA
A6: incomeMonthly (from PLU) | B6: =PLU_incomeMonthly -> 7140 | C6: A · input | D6: Clamped gross monthly. | F6: E · USER / FRONTEND OVERRIDE
A7: expenseMonthly (from PLU) | B7: =PLU_expenseMonthly -> 4141.2 | C7: A · input | D7: Annual spend = this × 12.
A8: mortgage (from PLU) | B8: =PLU_mortgage -> 192500 | C8: A · input | D8: Added to N_INC amount.
A9: life sum (from PLU) | B9: =PLU_lifeSum -> 428400 | C9: A · input | D9: N_INC have.
A10: investments (from PLU) | B10: =PLU_investments -> 104144 | C10: A · input | D10: Tagged wealth pot only. Cash is never allocated.
A11: lifeExpectancy used (from PLU) | B11: =PLU_leUsed -> 88 | C11: A · input | D11: yearsInRet = max(0, LE − retAge).
A13: O · GOAL-CARD SLIDERS / OVERRIDES — orange. Blank years keep the age rule
A14: lifestyle (1/2/3) | B14: 2 | C14: E · user / frontend override | D14: 1=frugal, 2=stress-free, 3=only the best. Default 2.
A15: retAge | B15: =ageOfRetirement -> 65 | C15: E · user / frontend override | D15: Default from Assumptions (65).
A16: targetYear | B16: =currentYear+eduYearsDefault -> 2036 | C16: E · user / frontend override | D16: Education horizon year.
A17: bequest | B17: 0 | C17: E · user / frontend override | D17: Added to N_INC amount.
A18: dependYears (blank = age rule) | C18: E · user / frontend override | D18: Blank or ≤0 → supportYears.
A19: incomeReplace (blank = income) | C19: E · user / frontend override | D19: Blank → incomeMonthly for CI / TPD.
A20: N_SAV stored | B20: 0 | C20: E · user / frontend override | D20: If > 0, this is N_SAV amount; else 1× annual income.
A21: N_PRP stored | B21: 0 | C21: E · user / frontend override | D21: If > 0, this is N_PRP amount; else 5× annual income.
A22: tag N_RET | B22: 0 | C22: E · user / frontend override | D22: Investments tagged to retirement, then grown at realReturn.
A23: tag N_EDU | B23: 0 | C23: E · user / frontend override | D23: apply_investment_pot walk order: RET, EDU, SAV, PRP.
A24: tag N_SAV | B24: 0 | C24: E · user / frontend override | D24: Takes from remaining investments after RET and EDU.
A25: tag N_PRP | B25: 0 | C25: E · user / frontend override | D25: Last in the walk.
A27: S · SYSTEM CURRENCY (USD) — user-currency inputs × USD per 1. The calculator below runs on these
A28: USD per 1 user-currency unit | B28: =FX_usdPerLocal -> 0.74 | C28: D · assumption / shared | D28: FX tab. #N/A if the currency is unknown.
A29: price level (option B) | B29: =FX_priceLevel -> 1 | C29: D · assumption / shared | D29: 1 under option A. Scales the USD fixed amounts.
A30: incomeMonthly USD | B30: =PLU_incomeMonthly*B28 -> 5283.6 | C30: C · calculated
A31: expenseMonthly USD | B31: =PLU_expenseMonthly*B28 -> 3064.488 | C31: C · calculated
A32: mortgage USD | B32: =PLU_mortgage*B28 -> 142450 | C32: C · calculated
A33: life sum USD | B33: =PLU_lifeSum*B28 -> 317016 | C33: C · calculated
A34: investments USD | B34: =PLU_investments*B28 -> 77066.56 | C34: C · calculated
A35: bequest USD | B35: =B17*B28 -> 0 | C35: C · calculated
A36: N_SAV stored USD | B36: =B20*B28 -> 0 | C36: C · calculated
A37: N_PRP stored USD | B37: =B21*B28 -> 0 | C37: C · calculated
A38: tag N_RET USD | B38: =B22*B28 -> 0 | C38: C · calculated
A39: tag N_EDU USD | B39: =B23*B28 -> 0 | C39: C · calculated
A40: tag N_SAV USD | B40: =B24*B28 -> 0 | C40: C · calculated
A41: tag N_PRP USD | B41: =B25*B28 -> 0 | C41: C · calculated
A42: incomeReplace USD | B42: =IF(B19="","",B19*B28) | C42: C · calculated | D42: Blank → income.
...

Sheet Plan Calculator
A1: Plan Calculator — selected persona. seedProducts / planProducts.ts. Suggested = enabled AND gap > 0.
A2: Selected persona | B2: =SelectedPersona -> P03 | C2: =IFERROR(INDEX(Personas!B$3:B$52,MATCH($B$2,Personas!$A$3:$A$52,0)),"") -> Daniel Koh | D2: Follows the dropdown on the Selected persona tab. | F2: A · INPUT DATA
A3: Attribute | B3: Value | C3: Kind | D3: Source / formula | F3: B · LLM PREDICTED DATA
A4: A · INPUT DATA — from People Like You and Need Calculator | F4: C · DETERMINISTICALLY CALCULATED
A5: take-home (from PLU) | B5: =PLU_takeHome -> 5712 | C5: A · input | D5: Surplus uses take-home, not gross income. | F5: D · ASSUMPTIONS / SHARED DATA
A6: expenseMonthly (from PLU) | B6: =PLU_expenseMonthly -> 4141.2 | C6: A · input | D6: types.ts availableBudget. | F6: E · USER / FRONTEND OVERRIDE
A7: N_INC on (from Need Calculator) | B7: =NC_on_N_INC -> TRUE | C7: A · input | D7: Effective enable after Need Calculator override.
A8: N_INC gap (from Need Calculator) | B8: =NC_gap_N_INC -> 446527 | C8: A · input | D8: remaining_gap.
A9: N_CRI on (from Need Calculator) | B9: =NC_on_N_CRI -> FALSE | C9: A · input | D9: Effective enable after Need Calculator override.
A10: N_CRI gap (from Need Calculator) | B10: =NC_gap_N_CRI -> 452382 | C10: A · input | D10: remaining_gap.
A11: N_TPD on (from Need Calculator) | B11: =NC_on_N_TPD -> FALSE | C11: A · input | D11: Effective enable after Need Calculator override.
A12: N_TPD gap (from Need Calculator) | B12: =NC_gap_N_TPD -> 613059 | C12: A · input | D12: remaining_gap.
A13: N_HOS on (from Need Calculator) | B13: =NC_on_N_HOS -> TRUE | C13: A · input | D13: Effective enable after Need Calculator override.
A14: N_HOS gap (from Need Calculator) | B14: =NC_gap_N_HOS -> 42840 | C14: A · input | D14: remaining_gap.
A15: N_RET on (from Need Calculator) | B15: =NC_on_N_RET -> TRUE | C15: A · input | D15: Effective enable after Need Calculator override.
A16: N_RET gap (from Need Calculator) | B16: =NC_gap_N_RET -> 1633487 | C16: A · input | D16: remaining_gap.
A17: N_EDU on (from Need Calculator) | B17: =NC_on_N_EDU -> FALSE | C17: A · input | D17: Effective enable after Need Calculator override.
A18: N_EDU gap (from Need Calculator) | B18: =NC_gap_N_EDU -> 94149 | C18: A · input | D18: remaining_gap.
A19: N_SAV on (from Need Calculator) | B19: =NC_on_N_SAV -> FALSE | C19: A · input | D19: Effective enable after Need Calculator override.
A20: N_SAV gap (from Need Calculator) | B20: =NC_gap_N_SAV -> 85680 | C20: A · input | D20: remaining_gap.
A21: N_PRP on (from Need Calculator) | B21: =NC_on_N_PRP -> TRUE | C21: A · input | D21: Effective enable after Need Calculator override.
A22: N_PRP gap (from Need Calculator) | B22: =NC_gap_N_PRP -> 428400 | C22: A · input | D22: remaining_gap.
A23: yearsToRet (from Need Calculator) | B23: =NC_yearsToRet -> 31 | C23: A · input | D23: Retirement contribution horizon.
A24: eduYears (from Need Calculator) | B24: =NC_eduYears -> 10 | C24: A · input | D24: EDU / SAV / PRP contribution horizon.
A26: D · ASSUMPTIONS / SHARED DATA
A27: protectionPremiumRate | B27: =protectionPremiumRate -> 0.00078 | C27: D · assumption / shared | D27: Dummy 0.00078. Future: premium-quote calculator API.
A28: FREE_BUDGET_SHARE | B28: =FREE_BUDGET_SHARE -> 0.5 | C28: D · assumption / shared | D28: Half of leftover surplus split across wealth needs.
A29: monthly step (user currency) | B29: =FX_monthlyStep -> 50 | C29: D · assumption / shared | D29: monthlyRoundStep (USD) as a nice step in user currency. SGD: 50.
A30: premium step (user currency) | B30: =FX_coverPremStep -> 10 | C30: D · assumption / shared | D30: coverPremRoundStep (USD) as a nice step in user currency. SGD: 10.
A31: realReturn | B31: =realReturn -> 0.018572825 | C31: D · assumption / shared | D31: annualPmtToHitFv for the wealth cap.
A33: C · DETERMINISTICALLY CALCULATED — suggested flags and protection sizing
A34: sug N_INC | B34: =AND(NC_on_N_INC,NC_gap_N_INC>0) -> TRUE | C34: C · calculated | D34: enabled AND gap > 0.
A35: sug N_CRI | B35: =AND(NC_on_N_CRI,NC_gap_N_CRI>0) -> FALSE | C35: C · calculated | D35: enabled AND gap > 0.
A36: sug N_TPD | B36: =AND(NC_on_N_TPD,NC_gap_N_TPD>0) -> FALSE | C36: C · calculated | D36: enabled AND gap > 0.
A37: sug N_HOS | B37: =AND(NC_on_N_HOS,NC_gap_N_HOS>0) -> TRUE | C37: C · calculated | D37: enabled AND gap > 0.
A38: sug N_RET | B38: =AND(NC_on_N_RET,NC_gap_N_RET>0) -> TRUE | C38: C · calculated | D38: enabled AND gap > 0.
A39: sug N_EDU | B39: =AND(NC_on_N_EDU,NC_gap_N_EDU>0) -> FALSE | C39: C · calculated | D39: enabled AND gap > 0.
A40: sug N_SAV | B40: =AND(NC_on_N_SAV,NC_gap_N_SAV>0) -> FALSE | C40: C · calculated | D40: enabled AND gap > 0.
A41: sug N_PRP | B41: =AND(NC_on_N_PRP,NC_gap_N_PRP>0) -> TRUE | C41: C · calculated | D41: enabled AND gap > 0.
A42: n wealth suggested | B42: =(B38*1)+(B39*1)+(B40*1)+(B41*1) -> 2 | C42: C · calculated | D42: Count of suggested wealth needs.
...

Sheet Budget Calculator
A1: Budget Calculator — selected persona. planAfford. Surplus is take-home minus expense.
A2: Selected persona | B2: =SelectedPersona -> P03 | C2: =IFERROR(INDEX(Personas!B$3:B$52,MATCH($B$2,Personas!$A$3:$A$52,0)),"") -> Daniel Koh | D2: Follows the dropdown on the Selected persona tab. | F2: A · INPUT DATA
A3: Attribute | B3: Value | C3: Kind | D3: Source / formula | F3: B · LLM PREDICTED DATA
A4: A · INPUT DATA — from People Like You and Plan Calculator | F4: C · DETERMINISTICALLY CALCULATED
A5: take-home (from PLU) | B5: =PLU_takeHome -> 5712 | C5: A · input | D5: types.ts availableBudget uses take-home. | F5: D · ASSUMPTIONS / SHARED DATA
A6: expenseMonthly (from PLU) | B6: =PLU_expenseMonthly -> 4141.2 | C6: A · input | D6: Not gross income. | F6: E · USER / FRONTEND OVERRIDE
A7: investments (from PLU) | B7: =PLU_investments -> 104144 | C7: A · input | D7: Cap for lumps.
A8: included N_INC premium | B8: =IF(PLAN_included_N_INC,PLAN_prem_N_INC,0) -> 350 | C8: A · input | D8: Only included protection.
A9: included N_CRI premium | B9: =IF(PLAN_included_N_CRI,PLAN_prem_N_CRI,0) -> 0 | C9: A · input
A10: included N_TPD premium | B10: =IF(PLAN_included_N_TPD,PLAN_prem_N_TPD,0) -> 0 | C10: A · input
A11: included N_HOS premium | B11: =IF(PLAN_included_N_HOS,PLAN_prem_N_HOS,0) -> 30 | C11: A · input
A12: investMth (from Plan) | B12: =PLAN_investMth -> 800 | C12: A · input | D12: Included wealth contributions.
A13: investLump (from Plan) | B13: =PLAN_investLump -> 0 | C13: A · input | D13: Included wealth lumps.
A15: D · ASSUMPTIONS / SHARED DATA
A16: FREE_BUDGET_SHARE | B16: =FREE_BUDGET_SHARE -> 0.5 | C16: D · assumption / shared | D16: Half of monthly surplus is the free budget.
A18: C · DETERMINISTICALLY CALCULATED — planAfford
A19: available | B19: =MAX(0,PLU_takeHome-PLU_expenseMonthly) -> 1570.8 | C19: C · calculated | D19: max(0, take-home − expense).
A20: free (50%) | B20: =ROUND(B19*FREE_BUDGET_SHARE,0) -> 785 | C20: C · calculated | D20: available × 50%, rounded.
A21: included prot prem / yr | B21: =IF(PLAN_included_N_INC,PLAN_prem_N_INC,0)+IF(PLAN_included_N_CRI,PLAN_prem_N_CRI,0)+IF(PLAN_included_N_TPD,PLAN_prem_N_TPD,0)+IF(PLAN_included_N_HOS,PLAN_prem_N_HOS,0) -> 380 | C21: C · calculated | D21: Sum of included protection premiums.
A22: premMth (display) | B22: =ROUND(B21/12,0) -> 32 | C22: C · calculated | D22: Annual premiums / 12.
A23: contribMth | B23: =PLAN_investMth -> 800 | C23: C · calculated | D23: Same as investMth.
A24: monthly | B24: =ROUND(PLAN_investMth+B21/12,0) -> 832 | C24: C · calculated | D24: contrib + prem/12.
A25: monthlyOver | B25: =B24-B20 -> 47 | C25: C · calculated | D25: > 0 means the plan exceeds the free budget.
A26: lumps | B26: =PLAN_investLump -> 0 | C26: C · calculated | D26: Included lumps.
A27: lumpOver | B27: =B26-PLU_investments -> -104144 | C27: C · calculated | D27: > 0 means lumps exceed current investments.

Sheet Scenario Visualizer
A1: Scenario Visualizer — selected persona. One deterministic path of SV CashFlowGeneratorV2 on GP's payload.
A2: Selected persona | B2: =SelectedPersona -> P03 | C2: =IFERROR(INDEX(Personas!B$3:B$52,MATCH($B$2,Personas!$A$3:$A$52,0)),"") -> Daniel Koh | D2: Follows the dropdown on the Selected persona tab. | F2: A · INPUT DATA
A3: Attribute | B3: Value | C3: Kind | D3: Source / formula | F3: B · LLM PREDICTED DATA
A4: A · INPUT DATA — effective session (People Like You, Need Calculator, Plan Calculator) | F4: C · DETERMINISTICALLY CALCULATED | H4: D · SV CPF TABLES — SocialSecurityR_SGP (by age at contribution)
A5: age | B5: =IFERROR(INDEX(Personas!C$3:C$52,MATCH($B$2,Personas!$A$3:$A$52,0)),"") -> 34 | C5: A · input | D5: Personas C. | F5: D · ASSUMPTIONS / SHARED DATA | H5: from age | I5: to age | J5: total rate | K5: employee rate | L5: OA share | M5: SA share | N5: MA share
A6: residency | B6: =IFERROR(INDEX(Personas!E$3:E$52,MATCH($B$2,Personas!$A$3:$A$52,0)),"") -> Citizen | C6: A · input | D6: Personas E. sv_payload.py sends CPF region R_SGP unless Foreigner. | F6: E · USER / FRONTEND OVERRIDE | H6: 0 | I6: 35 | J6: 0.37 | K6: 0.2 | L6: 0.6217 | M6: 0.1621 | N6: 0.2162
A7: incomeMonthly | B7: =PLU_incomeMonthly -> 7140 | C7: A · input | D7: Salary I_SAL = round(× 12). | H7: 36 | I7: 45 | J7: 0.37 | K7: 0.2 | L7: 0.5677 | M7: 0.1891 | N7: 0.2432
A8: take-home | B8: =PLU_takeHome -> 5712 | C8: A · input | D8: Investment contribution = take-home − spend. | H8: 46 | I8: 50 | J8: 0.37 | K8: 0.2 | L8: 0.5136 | M8: 0.2162 | N8: 0.2702
A9: expenseMonthly | B9: =PLU_expenseMonthly -> 4141.2 | C9: A · input | D9: PERSONAL_EXPENSE = round(× 12). | H9: 51 | I9: 55 | J9: 0.37 | K9: 0.2 | L9: 0.4055 | M9: 0.3108 | N9: 0.2837
A10: cash | B10: =PLU_cash -> 18378 | C10: A · input | D10: A_SAV, grows at interestRate. | H10: 56 | I10: 60 | J10: 0.325 | K10: 0.17 | L10: 0.4069 | M10: 0.2372 | N10: 0.3559
A11: investments | B11: =PLU_investments -> 104144 | C11: A · input | D11: INVESTMENT_PORTFOLIO, grows at investmentReturn. | H11: 61 | I11: 65 | J11: 0.235 | K11: 0.115 | L11: 0.1709 | M11: 0.317 | N11: 0.5121
A12: property | B12: =PLU_property -> 350000 | C12: A · input | D12: RESIDENTIAL_PROPERTY (illiquid). | H12: 66 | I12: 70 | J12: 0.165 | K12: 0.075 | L12: 0.0646 | M12: 0.258 | N12: 0.6774
A13: mortgage | B13: =PLU_mortgage -> 192500 | C13: A · input | D13: Mortgage loan, 20-year annuity at loanRate. | H13: 71 | I13: 999 | J13: 0.125 | K13: 0.05 | L13: 0.08 | M13: 0.08 | N13: 0.84
A14: life sum assured | B14: =PLU_lifeSum -> 428400 | C14: A · input | D14: Existing life policy (only when > 0).
A15: life premium / yr | B15: =PLU_lifePrem -> 1328 | C15: A · input | D15: regularPremium of the existing policy. | H15: D · CPF LIFE — BRS and monthly payout by (55 − age)+ + year − 2023
H16: row | I16: BRS | J16: payout × 1 | K16: payout × 2 | L16: payout × 3
A17: D · ASSUMPTIONS — SV helium tenant conf.ini and SocialSecurityR_SGP | H17: 0 | I17: 99400 | J17: 870 | K17: 1620 | L17: 2370
A18: lifeExpectancy (SV tenant) | B18: 100 | C18: D · assumption / shared | D18: helium conf.ini. The path runs to age 100, not the session LE. | H18: 1 | I18: 102900 | J18: 900 | K18: 1640 | L18: 2350
A19: savingsRate | B19: 0.01 | C19: D · assumption / shared | D19: helium conf.ini. Savings account growth; also the premium load (× 1.01). | H19: 2 | I19: 106500 | J19: 930 | K19: 1730 | L19: 2530
A20: ageOfRetirement | B20: =ageOfRetirement -> 65 | C20: D · assumption / shared | D20: Assumptions. | H20: 3 | I20: 110200 | J20: 950 | K20: 1780 | L20: 2610
A21: loan / premium term (years) | B21: 20 | C21: D · assumption / shared | D21: Mortgage remainingYears and existing policyTerm in sv_payload.py. | H21: 4 | I21: 114100 | J21: 980 | K21: 1840 | L21: 2690
A22: property rate premium | B22: 0.004 | C22: D · assumption / shared | D22: Property grows at max(0, assetReturn + 0.4%).
A23: currency shock share | B23: 0.66666667 | C23: D · assumption / shared | D23: Liquid assets fall by 2/3 of the slider.
A24: CPF ordinary-wage cap / yr | B24: 96000 | C24: D · assumption / shared | D24: SocialSecurityR_SGP.
A25: CPF MA cap | B25: 63000 | C25: D · assumption / shared | D25: Medisave excess moves to RA at payout age; MA is capped from then.
A26: CPF OA rate | B26: 0.025 | C26: D · assumption / shared
A27: CPF SA / MA rate | B27: 0.04 | C27: D · assumption / shared
A28: CPF RA / LIFE growth factor | B28: 1.04 | C28: D · assumption / shared | D28: RA and the CPF LIFE pot grow × 1.04 a year.
A29: BRS / payout growth | B29: 0.03 | C29: D · assumption / shared | D29: Past the 2027 row, and per year of payout age past 55.
A30: payout bonus per deferral year | B30: 0.07 | C30: D · assumption / shared | D30: × (1 + 7% × (payout age − 65)).
A32: C · DETERMINISTICALLY CALCULATED — sv_payload.py values as SV reads them
A33: years on the path (T) | B33: =MAX(SV_LE-SV_age,0) -> 66 | C33: C · calculated | D33: SV numYears = 100 − age.
A34: array length (T + 1) | B34: =SV_T+1 -> 67 | C34: C · calculated | D34: Asset / CPF columns run 0..T.
A35: years to retirement | B35: =MAX(SV_ret-SV_age,0) -> 31 | C35: C · calculated
A36: salary zero from index | B36: =IF(SV_dtr>=1,SV_dtr-1,SV_T-1) -> 30 | C36: C · calculated | D36: numpy arr[dtr−1:] = 0. When dtr = 0 only the last year is zeroed (SV keeps salary for retirees).
A37: salary / yr | B37: =IF(MOD(SV_income*12,1)=0.5,2*ROUND((SV_income*12)/2,0),ROUND(SV_income*12,0)) -> 85680 | C37: C · calculated | D37: I_SAL absoluteValue. Python round (half to even).
A38: spend / yr | B38: =IF(MOD(SV_expense*12,1)=0.5,2*ROUND((SV_expense*12)/2,0),ROUND(SV_expense*12,0)) -> 49694 | C38: C · calculated | D38: PERSONAL_EXPENSE absoluteValue. Python round (half to even).
A39: mortgage principal | B39: =INT(SV_mortgage) -> 192500 | C39: C · calculated | D39: int(mortgage).
A40: mortgage instalment / yr | B40: =IF(SV_mortgage>0,IF(MOD(IF(loanRate=0,SV_mortgage/SV_loanYears,SV_mortgage*loanRate/(1-(1+loanRate)^(-SV_loanYears))),1)=0.5,2*ROUND((IF(loanRate=0,SV_mortgage/SV_loanYears,SV_mortgage*loanRate/(1-(1+loanRate)^(-SV_loanYears))))/2,0),ROUND(IF(loanRate=0,SV_mortgage/SV_loanYears,SV_mortgage*loanRate/(1-(1+loanRate)^(-SV_loanYears))),0)),0) -> 13545 | C40: C · calculated | D40: Level annual annuity that clears the loan in 20 years, interest included (goal_math.annual_loan_payment). rate 0 → mortgage / 20. Paid from spend for 20 years. Python round (half to even).
A41: investment contribution / yr | B41: =IF(MOD(MAX(0,SV_takeHome-SV_expense),1)=0.5,2*ROUND((MAX(0,SV_takeHome-SV_expense))/2,0),ROUND(MAX(0,SV_takeHome-SV_expense),0)) -> 1571 | C41: C · calculated | D41: sv_payload.py sends the MONTHLY surplus; SV adds it once a year. Python round (half to even).
...

Sheet HappiU
A1: HappiU — selected persona. Deterministic HU score: expected values weighted by survival, on HU's cashflow rules.
A2: Selected persona | B2: =SelectedPersona -> P03 | C2: =IFERROR(INDEX(Personas!B$3:B$52,MATCH($B$2,Personas!$A$3:$A$52,0)),"") -> Daniel Koh | D2: Follows the dropdown on the Selected persona tab. | F2: A · INPUT DATA
A3: Attribute | B3: Value | C3: Kind | D3: Source / formula | F3: B · LLM PREDICTED DATA
A4: A · INPUT DATA — effective session (what hu_payload.py sends) | F4: C · DETERMINISTICALLY CALCULATED | H4: C · GOALS — enabled needs plus N_RET (GP always sends it)
A5: age | B5: =IFERROR(INDEX(Personas!C$3:C$52,MATCH($B$2,Personas!$A$3:$A$52,0)),"") -> 34 | C5: A · input | D5: Personas C. HU needs 18–83. | F5: D · ASSUMPTIONS / SHARED DATA | H5: type | I5: code | J5: in list | K5: need | L5: existing | M5: in plan | N5: benefit | O5: priority | P5: duration | Q5: D | R5: path | S5: w0 | T5: whl | U5: v(0) | V5: U base | W5: U pre | X5: U rec | Y5: U full | Z5: denominator | AA5: pre | AB5: post | AC5: flag | AD5: log priority | AE5: calibration | AF5: weight
