Workbook
Name inflationRate: Assumptions!$B$5
Name systemCurrency: Assumptions!$B$22
Name fxMode: Assumptions!$B$23
Name PPP_BASE_COUNTRY: Assumptions!$B$78
Name priceLevelOn: Assumptions!$B$24
Name LTC_COST: Assumptions!$B$25
Name LTC_START_AGE: Assumptions!$B$26
Name interestRate: Assumptions!$B$6
Name loanRate: Assumptions!$B$7
Name incomeGrowthRate: Assumptions!$B$8
Name investmentReturn: Assumptions!$B$9
Name assetReturn: Assumptions!$B$10
Name realReturn: Assumptions!$B$11
Name ageOfRetirement: Assumptions!$B$14
Name lifeExpectancyDefault: Assumptions!$B$15
Name currentYear: Assumptions!$B$16
Name endAge: Assumptions!$B$17
Name RET_LIFESTYLE_FRUGAL: Assumptions!$B$28
Name RET_LIFESTYLE_STRESSFREE: Assumptions!$B$29
Name RET_LIFESTYLE_ONLYTHEBEST: Assumptions!$B$30
Name INC_SUPPORT_MIN: Assumptions!$B$31
Name INC_SUPPORT_MAX: Assumptions!$B$32
Name INC_SUPPORT_PIVOT_AGE: Assumptions!$B$33
Name CRI_YEARS: Assumptions!$B$34
Name CRI_COST: Assumptions!$B$35
Name TPD_YEARS: Assumptions!$B$36
Name TPD_COST: Assumptions!$B$37
Name HOS_MONTHS: Assumptions!$B$38
Name EDU_COST: Assumptions!$B$39
Name EDU_TARGET_AGE: Assumptions!$B$40
Name SAV_TARGET_AGE: Assumptions!$B$18
Name PRP_TARGET_AGE: Assumptions!$B$19
Name SAV_INCOME_MULT: Assumptions!$B$41
Name PRP_INCOME_MULT: Assumptions!$B$42
Name PAC_YEARS: Assumptions!$B$43
Name PAC_COST: Assumptions!$B$44
Name LON_AGE: Assumptions!$B$45
Name spendShareBase: Assumptions!$B$47
Name spendSharePerDependant: Assumptions!$B$48
Name spendShareCap: Assumptions!$B$49
Name assetsSaveShare: Assumptions!$B$50
Name workStartAge: Assumptions!$B$51
Name liabilityRatio: Assumptions!$B$52
Name CASH_SAVINGS_SHARE: Assumptions!$B$53
Name INVESTMENTS_SHARE: Assumptions!$B$54
Name propertyLow: Assumptions!$B$55
Name propertyMid: Assumptions!$B$56
Name propertyHigh: Assumptions!$B$57
Name propertyIncomeLow: Assumptions!$B$58
Name propertyIncomeHigh: Assumptions!$B$59
Name PROPERTY_LTV: Assumptions!$B$60
Name lifePremiumRate: Assumptions!$B$61
Name lifeRoundUnit: Assumptions!$B$62
Name protectionPremiumRate: Assumptions!$B$65
Name FREE_BUDGET_SHARE: Assumptions!$B$66
Name lumpRoundStep: Assumptions!$B$67
Name monthlyRoundStep: Assumptions!$B$68
Name coverPremRoundStep: Assumptions!$B$69
Name coverSliderPremFloor: Assumptions!$B$70
Name annualBudget: Assumptions!$B$73

Sheet Overview
A1: FinPlan360 calculation components — live code, September 2026
A2: Yellow = type here. Orange = override (leave blank to keep the calculated value). Pick the persona on the Selected persona tab; every later tab follows that id. Gold = persona input, blue = LLM, orange = user / Money-page override, green = calculated, purple = assumptions. FX converts local amounts to USD. Validation applies USD-only rules. CPF is its own tab and is on only when the country switch says so (Singapore on, others off). HappiU and Scenario Visualizer are mapped here but scored / projected in HU and SV.
A3: Component | B3: Owner | C3: Reads | D3: Writes | E3: How it calculates (code) | F3: Code | G3: Tab | H3: HTTP / UI
A4: CPF | B4: GP pipeline (Singapore only) | C4: country, residency, age, incomeMonthly. Country switch on the CPF tab. | D4: employee CPF, take-home. 0 / income when CPF is off. | E4: On only when the country table (or orange override) is TRUE. Singapore Citizen/PR: employee CPF = floor(min(gross, OW_CEILING) × age-band rate). Foreigner → 0. Any other country → off, take-home = gross. src/cpf.py. | F4: src/cpf.py | G4: CPF | H4: Inside POST /v1/predict (take-home)
A5: People Like You | B5: GP pipeline | C5: age / DOB, occupation, gender, dependents, residency. CPF box for take-home. Does not read Assumptions. | D5: incomeMonthly, expenseMonthly, cash, investments, property, mortgage, one Life Protection policy, lifeExpectancy, isSmoker. | E5: LLM proposes gross monthly income and lifestyle flags. Income is clamped to the Singapore occupation band. Employee CPF = floor(min(gross, 8000) × age-band rate); 0 if Foreigner. expenseMonthly = round(take-home × min(67.5% + 5pp × dependents, 90%), 2). Liquid assets = max(0, surplus × 12 × 0.5 × (age − 21)), then cash 15% / investments 85%. If the model says they own a home: property from income band, mortgage = round(property × 55%). Assumed life cover = max(mortgage rounded up to S$100k, 5 × annual income if dependents > 0); premium = round(sum × 0.31%). PLU liabilities (= assets × 0.7) is not the mortgage. If this step fails, predict returns 503. | F5: src/pipeline/people_like_you.py, src/cpf.py, src/predict.py _apply_plu | G5: People Like You | H5: POST /v1/predict (first of three)
A6: Need Profiler | B6: GP pipeline | C6: Age, gender, dependents, occupation, smoker, income, expense, liquid assets, PLU liabilities, hospital/ward/lifestyle/sports, car/home/travel flags. Existing cover is hard-coded 0. No Assumptions. No LLM. | D6: needs[].enabled, needs[].priority, needs[].weightageScore. Four UNIFIED types on: two protection + two growth (retirement always one of the growth pair). | E6: Twelve AI labels are scored as Σ (factor_weight × option_weight), rounded to 2 dp, then min–max scaled 0–10. Income / expense / assets / liabilities convert local × FX to USD, then retuned USD bands. Car ownership, home ownership, travel, and existing life / CI cover have factor weights but no matching weight_options, so they add 0. select_unified_top ignores top_n (app.py still passes 4). If has_property, N_PRP replaces N_SAV in the second growth slot. priority = 5 if scaled score > 7 else 3. Personal accident / motor / travel / farewell are scored and dropped. Orange Enable? columns let you force a need on or off. | F6: src/pipeline/need_profiler.py, src/pipeline/prompts/Need_profiler.json, src/app.py top_n=4 | G6: Need Profiler | H6: POST /v1/predict
A7: Need Calculator | B7: GP pipeline | C7: Money attributes, enabled needs, goal-card sliders (lifestyle, retAge, targetYear, incomeReplaceMonthly, dependYears, bequest, monthlyContribution, tagged existing), Assumptions rates, Need parameters. | D7: For every UNIFIED type: needAmount, have, gap. Copies ageOfRetirement from the retirement row. | E7: realReturn = max(0, (1 + investmentReturn) / (1 + inflationRate) − 1). N_RET = annualSpend × (1+realReturn)^T × a(realReturn, n), n = min(LE,99) − retAge. N_INC = bequest + mortgage + ordinary annuity of annual spend over supportYears = min(max(10, 50 − age), 25). N_CRI / N_TPD = annuity-due of replacement income for 3 / 5 years + S$200,000. N_HOS = income × 6. N_EDU = 75,000 × (1 + inflation)^(targetYear − thisYear). N_SAV / N_PRP = stored needAmount if > 0, else 1× / 5× annual income. Protection have = policy sum (life is seeded by PLU). Wealth have = tagged investments only, grown at realReturn; cash is never allocated. Amounts are computed for all eight types even when a need is off. Orange Enable? and slider columns are the goal-card inputs. | F7: src/pipeline/need_calculator.py evaluate_session, src/pipeline/goal_math.py, src/hu_payload.py need_existing / apply_investment_pot | G7: Need Calculator | H7: POST /v1/predict and POST /v1/needs
A8: Goal cards | B8: GP UI | C8: Last calculator row (have, gap, stored sliders). | D8: Slider fields on the need; then POST /v1/needs (debounced). Does not recompute amounts in the browser. | E8: fillNeedEdit reads stored fields. patchNeedInputs writes lifestyle / retAge / targetYear / existing / … onto the session. Retirement stays on. The Score/Plan cap of four needs is UI-only (needEdit.capEnabledNeeds); this workbook lets you switch any need. | F8: frontend/src/lib/needEdit.ts | G8: Need Calculator (slider columns) | H8: Score and Plan screens
A9: Plan Calculator | B9: GP UI | C9: Enabled needs with gap > 0, take-home surplus, Assumptions inflationRate / investmentReturn / ageOfRetirement. | D9: planSum + planPrem (protection), planMth + planLump (wealth), investMth / investLump totals, plansOff. | E9: Suggested = enabled AND gap > 0. Default planSum = round(gap). planPrem = dummy indicative round((sum × 0.00078) / 10) × 10 (future: premium-quote API). Wealth horizon = years to retirement, or targetYear − this year. Lump / monthly caps = the amount that alone grows to the gap at realReturn (round up to S$1,000 / S$50). Default monthly = round((max(0, take-home − expense) × 12 − all protection premiums) × 50% / 12 / n_wealth / 50) × 50, then min(share, cap). Default lump = 0. Orange Include? columns are plansOff. | F9: frontend/src/lib/planProducts.ts, frontend/src/lib/local.ts seedProducts | G9: Plan Calculator | H9: Plan screen (not an HTTP engine)
A10: Budget Calculator | B10: GP UI | C10: take-home, expenseMonthly, investments, included planPrem / planMth / planLump. Not the economic rates. | D10: Nothing on the session. Plan-screen affordability only. | E10: available = max(0, takeHomeMonthly − expenseMonthly). free = round(available × 0.5). monthly = round(wealth contributions + protection premiums / 12). monthlyOver = monthly − free. lumpOver = wealth lumps − investments. Separate from the HappiU envelope (annualBudget 1500). | F10: planAfford in frontend/src/lib/planProducts.ts; availableBudget in types.ts | G10: Budget Calculator | H10: Plan screen
A11: FX | B11: Workbook only (not an HTTP engine) | C11: Personas currency + effective session money fields from People Like You. | D11: USD per 1 local, and each money field in USD. Validation reads these; engines stay local. | E11: Lookup ISO code in the FX rate table (USD per 1 local unit). USD = local × rate. Example: 5,000 SGD × 0.74 = 3,700 USD; 5,000 VND × 0.000038 = 0.19 USD. Edit the rate table on this tab. People Like You still stores local currency. | F11: Workbook FX tab (no src module — validation helper) | G11: FX | H11: Not in the live pipeline
A12: HappiU | B12: HU, via GP | C12: Whole session. Assumptions rates, CPF (inside HU), riskProfile, plan fields when set. Need amounts already stored. | D12: preHappiU, postHappiU. GP does not run the Monte Carlo. | E12: GP maps the session (src/hu_payload.py). Salary is gross incomeMonthly. N_HOS is renamed N_HSP. If retirement is off, GP still sends a synthetic N_RET = expense × 12 × (lifeExpectancy − retAge). Before a plan: benefitAmount = needAmount rounded to S$50,000, budget 200. With a plan: planSum / planPrem. This workbook does not score HappiU. | F12: src/hu_payload.py → POST /v1/score → HU | G12: Assumptions (envelope only) | H12: POST /v1/score
A13: Scenario Visualizer | B13: SV, via GP | C13: Session after Plan, all six rates, ageOfRetirement, endAge, stress chips. CPF inside SV. | D13: Year-by-year wealth path. GP does not run the year step. | E13: preWealth = session without the plan; postWealth = plus included planMth / planLump / planSum / planPrem. svNumSims defaults to 20. Investment contribution = max(0, take-home − expenseMonthly) once a year. This workbook does not project the path. | F13: src/sv_payload.py → POST /v1/project → SV | G13: Assumptions (stress catalogue) | H13: POST /v1/project
A14: Journey order (one session, each step adds attributes)
A15: Shared inputs (Assumptions · CPF · Need parameters · Risk · Stress events) → About you → CPF (on for Singapore only) → People Like You (or the customer edits the same money fields) → Need Profiler → Need Calculator → HappiU (no plan) → Plan Calculator → Budget Calculator → Scenario Visualizer → HappiU (with plan). Workbook-only: FX (local → USD) then Validation (USD rules).
A17: UNIFIED types in code order: N_INC, N_CRI, N_TPD, N_HOS (protection) · N_RET, N_EDU, N_SAV, N_PRP (wealth). Goal-card sliders live on the Need Calculator tab. Discrepancies lists remaining multi-country / multi-currency work.

Sheet Dictionary
A1: Dictionary — needs (N_), risks (R_) and parameter prefixes
A2: N_xxx = need. R_xxx = the risk or event that triggers it (N_CRI ↔ R_CRI; N_INC ↔ R_DEA). · Parameters are named <PREFIX>_<WHAT> in upper case, with the need's 3-letter prefix (CRI_COST, HOS_MONTHS). · Protection · calculator and Wealth · calculator needs get amount / have / gap. Coverage · parked needs are scored only. · One name per need in every component (e.g. TPD, never Disability or PTD). Where an engine still differs (HU: N_HSP, PTD) it is listed as open. · Code (src/, frontend/) still uses the old parameter names and 8 needs until the code follows V0-16.
A4: NEEDS
A5: Code | B5: Risk | C5: Prefix | D5: Category | E5: App label | F5: Profiler label (key) | G5: HappiU | H5: Scenario Visualizer | I5: Calculator | J5: Parameters | K5: Status
A6: N_INC | B6: R_DEA | C6: INC | D6: Protection · calculator | E6: Income & family protection | F6: Life Protection (life_protection) | G6: N_INC | H6: premium | I6: bequest + mortgage + PV of annual spend over support years | J6: INC_SUPPORT_MIN / MAX / PIVOT_AGE | K6: Live
A7: N_CRI | B7: R_CRI | C7: CRI | D7: Protection · calculator | E7: Critical illness | F7: Critical Illness (critical_illness) | G7: N_CRI | H7: premium | I7: annuity-due of income for CRI_YEARS + CRI_COST | J7: CRI_YEARS, CRI_COST | K7: Live
A8: N_TPD | B8: R_TPD | C8: TPD | D8: Protection · calculator | E8: Total & permanent disability (TPD) | F8: TPD (JSON key: disability) | G8: N_TPD (HU engine internals still say PTD: rename there) | H8: premium | I8: annuity-due of income for TPD_YEARS + TPD_COST | J8: TPD_YEARS, TPD_COST | K8: Live
A9: N_HOS | B9: R_HOS | C9: HOS | D9: Protection · calculator | E9: Hospitalisation | F9: Hospitalization (hospitalization) | G9: N_HSP: GP renames N_HOS → N_HSP in hu_payload.py because the HU engine only knows N_HSP | H9: premium | I9: incomeMonthly × HOS_MONTHS | J9: HOS_MONTHS | K9: Live. Open: one code (N_HOS) in GP and HU
A10: N_PAC | B10: R_PAC | C10: PAC | D10: Protection · calculator | E10: Personal accident (new) | F10: Personal Accident (personal_accident) | G10: N_PAC (HU engine supports it; GP does not send it yet) | H10: premium | I10: annuity-due of income for PAC_YEARS + PAC_COST | J10: PAC_YEARS, PAC_COST | K10: Agreed V0-18 (Excel). Code and HappiU payload to follow
A11: N_ADB | B11: R_ADB | C11: ADB | D11: Protection · candidate | E11: Accidental death | F11: none (no profiler label) | G11: N_ADB (HU engine supports it, death-type goal like N_INC) | H11: — | I11: not defined yet (proposal: lump like N_INC, paid only on accidental death) | J11: ADB_* (to define) | K11: Added V0-17 to the dictionary. No calculator, not scored
A12: N_LTC | B12: R_LTC | C12: LTC | D12: Protection · calculator | E12: Long-term care | F12: none (no profiler label) | G12: not sent (HU engine has no LTC) | H12: premium | I12: annuity-due of LTC_COST over care years (LTC start age → life expectancy) | J12: LTC_COST, LTC_START_AGE (front-end input) | K12: New V0-19. Off unless the customer switches it on
A13: N_RET | B13: R_LON | C13: RET | D13: Wealth · calculator | E13: Private retirement | F13: Retirement (retirement) | G13: N_RET | H13: RET pot | I13: annual spend × lifestyle, grown to retirement, × annuity over years in retirement | J13: RET_LIFESTYLE_FRUGAL / STRESSFREE / ONLYTHEBEST; LON_AGE (R_LON) | K13: Live. R_LON stress: need re-sized to LON_AGE 99
A14: N_EDU | B14: — | C14: EDU | D14: Wealth · calculator | E14: Child's university education | F14: Education (education) | G14: N_EDU | H14: goal pot | I14: EDU_COST grown at inflation to target year | J14: EDU_COST, EDU_TARGET_AGE (50) | K14: Live
A15: N_SAV | B15: — | C15: SAV | D15: Wealth · calculator | E15: Savings goal | F15: General Savings (general_savings) | G15: N_SAV | H15: goal pot | I15: stored amount, else SAV_INCOME_MULT × annual income | J15: SAV_INCOME_MULT, SAV_TARGET_AGE (40) | K15: Live. No longer swapped with N_PRP
A16: N_PRP | B16: — | C16: PRP | D16: Wealth · calculator | E16: Home purchase | F16: none (no home-purchase label) | G16: N_PRP | H16: goal pot | I16: stored amount, else PRP_INCOME_MULT × annual income | J16: PRP_INCOME_MULT, PRP_TARGET_AGE (33) | K16: Separated from Home Protection. Off unless the customer switches it on
... A20: — | B20: — | C20: — | D20: Dropped | E20: Farewell | F20: Farewell (farewell) | G20: funeral lump dropped | H20: — | I20: — | J20: funeralLump removed | K20: Dropped V0-16
A22: RISKS AND STRESS EVENTS
A23: Code | B23: Was (id) | C23: Label | D23: Need | E23: Kind
A24: R_DEA | B24: death | C24: Death | D24: N_INC | E24: Need risk
A25: R_CRI | B25: ci | C25: Critical illness | D25: N_CRI | E25: Need risk
A26: R_TPD | B26: tpd | C26: Total & permanent disability | D26: N_TPD | E26: Need risk
A27: R_HOS | B27: hosp | C27: Hospitalisation | D27: N_HOS | E27: Need risk
A28: R_PAC | B28: pa | C28: Personal accident | D28: N_PAC | E28: Need risk
A29: R_ADB | B29: — | C29: Accidental death | D29: N_ADB | E29: Need risk (no stress event yet)
A30: R_LON | B30: — (new V0-18) | C30: Longevity: live until LON_AGE (99) | D30: N_RET | E30: Need risk · stress event
A31: R_LTC | B31: care | C31: Long-term care | D31: N_LTC | E31: Need risk · stress event
A32: R_MKT | B32: crash | C32: Market crash | D32: — | E32: Market event
A33: R_CCY | B33: ccy | C33: Currency shock | D33: — | E33: Market event
A34: R_INF | B34: infl | C34: Inflation shock | D34: — | E34: Market event
... A38: R_BAB | B38: baby | C38: Newborn | D38: — | E38: Life event
A40: PARAMETER NAMES (Assumptions named cells)
A41: New name | B41: Was | C41: Need
A42: INC_SUPPORT_MIN | B42: lifeSupportMin | C42: N_INC
A43: INC_SUPPORT_MAX | B43: lifeSupportMax | C43: N_INC
A44: INC_SUPPORT_PIVOT_AGE | B44: lifeSupportPivotAge | C44: N_INC
A45: CRI_YEARS | B45: CI_YEARS | C45: N_CRI
A46: CRI_COST | B46: CI_COST | C46: N_CRI
A47: TPD_YEARS | B47: TPD_YEARS | C47: N_TPD
A48: TPD_COST | B48: TPD_COST | C48: N_TPD
A49: HOS_MONTHS | B49: HOSP_MONTHS | C49: N_HOS
...

Sheet Selected persona
A1: Selected persona — pick one id here. Every calculation tab follows this cell.
A2: Selected persona | B2: P01 | C2: =IFERROR(INDEX(Personas!B$3:B$52,MATCH($B$2,Personas!$A$3:$A$52,0)),"") | D2: This is the only picker. CPF, People Like You, Need Profiler, Need Calculator, Plan, Budget, FX, and Validation follow this cell. | F2: A · INPUT DATA
A3: Attribute | B3: Value | C3: Kind | D3: Source / formula | F3: B · LLM PREDICTED DATA
A4: A · ABOUT YOU — from the Personas row (edit there) | F4: C · DETERMINISTICALLY CALCULATED
A5: name | B5: =IFERROR(INDEX(Personas!B$3:B$52,MATCH($B$2,Personas!$A$3:$A$52,0)),"") | C5: A · input | D5: Personas B. | F5: D · ASSUMPTIONS / SHARED DATA
A6: age | B6: =IFERROR(INDEX(Personas!C$3:C$52,MATCH($B$2,Personas!$A$3:$A$52,0)),"") | C6: A · input | D6: Personas C. | F6: E · USER / FRONTEND OVERRIDE
A7: gender | B7: =IFERROR(INDEX(Personas!D$3:D$52,MATCH($B$2,Personas!$A$3:$A$52,0)),"") | C7: A · input | D7: Personas D.
A8: residency | B8: =IFERROR(INDEX(Personas!E$3:E$52,MATCH($B$2,Personas!$A$3:$A$52,0)),"") | C8: A · input | D8: Personas E.
A9: country | B9: =IFERROR(INDEX(Personas!F$3:F$52,MATCH($B$2,Personas!$A$3:$A$52,0)),"") | C9: A · input | D9: Personas F. CPF on/off uses this.
A10: occupation | B10: =IFERROR(INDEX(Personas!G$3:G$52,MATCH($B$2,Personas!$A$3:$A$52,0)),"") | C10: A · input | D10: Personas G. Income clamp band.
A11: dependents | B11: =IFERROR(INDEX(Personas!H$3:H$52,MATCH($B$2,Personas!$A$3:$A$52,0)),"") | C11: A · input | D11: Personas H.
A12: maritalStatus | B12: =IFERROR(INDEX(Personas!I$3:I$52,MATCH($B$2,Personas!$A$3:$A$52,0)),"") | C12: A · input | D12: Personas I. Blank = infer on People Like You.
A13: what this row varies | B13: =IFERROR(INDEX(Personas!AD$3:AD$52,MATCH($B$2,Personas!$A$3:$A$52,0)),"") | C13: A · input | D13: Personas AD. Why this persona exists.
A15: B · LLM PREDICTED — from the Personas row (edit there)
A16: incomeMonthly (LLM) | B16: =IFERROR(INDEX(Personas!J$3:J$52,MATCH($B$2,Personas!$A$3:$A$52,0)),"") | C16: B · LLM predicted | D16: Personas J. Before clamp and CPF.
A17: currency | B17: =IFERROR(INDEX(Personas!K$3:K$52,MATCH($B$2,Personas!$A$3:$A$52,0)),"") | C17: B · LLM predicted | D17: Personas K. FX looks this up.
A18: risk ability | B18: =IFERROR(INDEX(Personas!L$3:L$52,MATCH($B$2,Personas!$A$3:$A$52,0)),"") | C18: B · LLM predicted | D18: Personas L.
A19: price sensitivity | B19: =IFERROR(INDEX(Personas!M$3:M$52,MATCH($B$2,Personas!$A$3:$A$52,0)),"") | C19: B · LLM predicted | D19: Personas M.
A20: owns property | B20: =IFERROR(INDEX(Personas!N$3:N$52,MATCH($B$2,Personas!$A$3:$A$52,0)),"") | C20: B · LLM predicted | D20: Personas N.
A21: owns car | B21: =IFERROR(INDEX(Personas!O$3:O$52,MATCH($B$2,Personas!$A$3:$A$52,0)),"") | C21: B · LLM predicted | D21: Personas O.
A22: is smoker | B22: =IFERROR(INDEX(Personas!U$3:U$52,MATCH($B$2,Personas!$A$3:$A$52,0)),"") | C22: B · LLM predicted | D22: Personas U.
A23: life expectancy | B23: =IFERROR(INDEX(Personas!V$3:V$52,MATCH($B$2,Personas!$A$3:$A$52,0)),"") | C23: B · LLM predicted | D23: Personas V.
A24: retirement lifestyle | B24: =IFERROR(INDEX(Personas!T$3:T$52,MATCH($B$2,Personas!$A$3:$A$52,0)),"") | C24: B · LLM predicted | D24: Personas T.
A26: C · EFFECTIVE SESSION — after CPF, People Like You, and Money-page overrides
A27: CPF on | B27: =CPF_on | C27: C · calculated | D27: From the CPF tab.
A28: incomeMonthly | B28: =PLU_incomeMonthly | C28: C · calculated | D28: Clamped LLM income.
A29: take-home | B29: =PLU_takeHome | C29: C · calculated | D29: Gross minus employee CPF when CPF is on.
A30: expenseMonthly | B30: =PLU_expenseMonthly | C30: C · calculated | D30: Override if Personas W is set.
A31: cash | B31: =PLU_cash | C31: C · calculated | D31: Cash & Savings.
A32: investments | B32: =PLU_investments | C32: C · calculated
A33: property | B33: =PLU_property | C33: C · calculated | D33: 0 if renter.
A34: mortgage | B34: =PLU_mortgage | C34: C · calculated
A35: PLU liabilities | B35: =PLU_liabilities | C35: C · calculated | D35: Not the mortgage.
A36: life sum assured | B36: =PLU_lifeSum | C36: C · calculated

Sheet Personas
A1: A · INPUT DATA — About you (typed / session) | J1: B · LLM PREDICTED DATA — 13 fields from people_like_you_all_fields.json | W1: E · USER / FRONTEND OVERRIDE — Money page (blank = keep People Like You calculated) | AD1: notes | AF1: A · INPUT DATA
A2: id | B2: name | C2: age | D2: gender | E2: residency | F2: country | G2: occupation | H2: dependents | I2: maritalStatus (blank = infer) | J2: income | K2: currency | L2: risk_ability | M2: price_sensitivity | N2: property | O2: car | P2: ward_type | Q2: hospitalization_type | R2: travelling | S2: sports | T2: retirement_lifestyle | U2: is_smoker | V2: life_expectancy | W2: expenseMonthly | X2: cash (Cash & Savings) | Y2: investments | Z2: property value | AA2: mortgage (loans) | AB2: PLU liabilities | AC2: life sum assured | AD2: What this row varies | AF2: B · LLM PREDICTED DATA
A3: P01 | B3: Aisha Rahman | C3: 22 | D3: Female | E3: Citizen | F3: Singapore | G3: Nurse | H3: 0 | J3: 4200 | K3: SGD | L3: conservative | M3: high | N3: FALSE | O3: FALSE | P3: Ward | Q3: Public | R3: FALSE | S3: Yoga | T3: Basic | U3: FALSE | V3: 86 | AD3: Nurse; age 22; Citizen; 0 dep; rent; non-smoker | AF3: C · DETERMINISTICALLY CALCULATED
A4: P02 | B4: Wei Ling Tan | C4: 27 | D4: Male | E4: PR | F4: Singapore | G4: Teacher | H4: 0 | J4: 6020 | K4: SGD | L4: moderate | M4: medium | N4: FALSE | O4: TRUE | P4: Double | Q4: Private | R4: TRUE | S4: Running | T4: Comfortable | U4: FALSE | V4: 81 | AD4: Teacher; age 27; PR; 0 dep; rent; non-smoker | AF4: D · ASSUMPTIONS / SHARED DATA
A5: P03 | B5: Daniel Koh | C5: 34 | D5: Female | E5: Citizen | F5: Singapore | G5: Accountant | H5: 1 | J5: 7140 | K5: SGD | L5: moderate | M5: medium | N5: TRUE | O5: TRUE | P5: Single | Q5: Private | R5: TRUE | S5: Swimming | T5: Comfortable | U5: FALSE | V5: 88 | AD5: Accountant; age 34; Citizen; 1 dep; home; non-smoker | AF5: E · USER / FRONTEND OVERRIDE
A6: P04 | B6: Priya Nair | C6: 41 | D6: Male | E6: Citizen | F6: Singapore | G6: Marketing Manager | H6: 2 | J6: 4550 | K6: SGD | L6: conservative | M6: high | N6: TRUE | O6: TRUE | P6: Ward | Q6: Public | R6: FALSE | S6: I dont do sports | T6: frugal | U6: TRUE | V6: 78 | AD6: Marketing Manager; age 41; Citizen; 2 dep; home; smoker
A7: P05 | B7: Marcus Lim | C7: 47 | D7: Female | E7: Foreigner | F7: Singapore | G7: Software Engineer | H7: 2 | J7: 5000 | K7: SGD | L7: aggressive | M7: high | N7: TRUE | O7: FALSE | P7: A | Q7: Private | R7: TRUE | S7: Adventurous Sports | T7: only the best | U7: FALSE | V7: 90 | AD7: Software Engineer; age 47; Foreigner; 2 dep; home; non-smoker
A8: P06 | B8: Hannah Wong | C8: 32 | D8: Male | E8: Citizen | F8: Singapore | G8: Doctor | H8: 1 | J8: 13910 | K8: SGD | L8: moderate | M8: medium | N8: TRUE | O8: TRUE | P8: B | Q8: Public | R8: TRUE | S8: Life style activities | T8: stress-free | U8: FALSE | V8: 83 | AD8: Doctor; age 32; Citizen; 1 dep; home; non-smoker
A9: P07 | B9: Julian Chee | C9: 54 | D9: Female | E9: PR | F9: Singapore | G9: Investment Banker | H9: 0 | J9: 5525 | K9: SGD | L9: conservative | M9: high | N9: TRUE | O9: TRUE | P9: Single | Q9: Private | R9: FALSE | S9: Walking | T9: Basic | U9: FALSE | V9: 89 | AD9: Investment Banker; age 54; PR; 0 dep; home; non-smoker
A10: P08 | B10: Mei Fen Ong | C10: 60 | D10: Male | E10: Citizen | F10: Singapore | G10: CEO | H10: 3 | J10: 5975 | K10: SGD | L10: conservative | M10: high | N10: TRUE | O10: TRUE | P10: Ward | Q10: Public | R10: FALSE | S10: I dont do sports | T10: frugal | U10: TRUE | V10: 76 | AD10: CEO; age 60; Citizen; 3 dep; home; smoker
A11: P09 | B11: Hafiz Abdullah | C11: 25 | D11: Female | E11: Citizen | F11: Singapore | G11: Baker | H11: 0 | J11: 3350 | K11: SGD | L11: moderate | M11: high | N11: FALSE | O11: FALSE | P11: Ward | Q11: Public | R11: TRUE | S11: HIIT | T11: Comfortable | U11: FALSE | V11: 87 | AD11: Baker; age 25; Citizen; 0 dep; rent; non-smoker
A12: P10 | B12: Siti Hassan | C12: 37 | D12: Male | E12: Foreigner | F12: Singapore | G12: Driver | H12: 2 | J12: 4250 | K12: SGD | L12: aggressive | M12: high | N12: FALSE | O12: TRUE | P12: Double | Q12: Private | R12: TRUE | S12: Football | T12: Luxurious | U12: FALSE | V12: 80 | AD12: Driver; age 37; Foreigner; 2 dep; rent; non-smoker
A13: P11 | B13: Aisha Ng | C13: 51 | D13: Female | E13: Citizen | F13: Singapore | G13: Nurse | H13: 1 | J13: 7140 | K13: SGD | L13: moderate | M13: medium | N13: TRUE | O13: TRUE | P13: A | Q13: Private | R13: TRUE | S13: Pilates | T13: only the best | U13: FALSE | V13: 91 | AD13: Nurse; age 51; Citizen; 1 dep; home; non-smoker
A14: P12 | B14: Wei Ling Chua | C14: 66 | D14: Male | E14: Citizen | F14: Singapore | G14: Teacher | H14: 0 | J14: 9800 | K14: SGD | L14: conservative | M14: medium | N14: TRUE | O14: FALSE | P14: Ward | Q14: Public | R14: FALSE | S14: I dont do sports | T14: Basic | U14: FALSE | V14: 85 | AD14: Teacher; age 66; Citizen; 0 dep; home; non-smoker
A15: P13 | B15: Daniel Lee | C15: 30 | D15: Female | E15: PR | F15: Singapore | G15: Accountant | H15: 1 | J15: 6580 | K15: SGD | L15: moderate | M15: medium | N15: FALSE | O15: TRUE | P15: Double | Q15: Public | R15: FALSE | S15: Running | T15: Comfortable | U15: TRUE | V15: 79 | AD15: Accountant; age 30; PR; 1 dep; rent; smoker
A16: P14 | B16: Priya Goh | C16: 44 | D16: Male | E16: Citizen | F16: Singapore | G16: Marketing Manager | H16: 4 | J16: 4775 | K16: SGD | L16: aggressive | M16: high | N16: TRUE | O16: TRUE | P16: Single | Q16: Private | R16: TRUE | S16: Golf | T16: Luxurious | U16: FALSE | V16: 84 | AD16: Marketing Manager; age 44; Citizen; 4 dep; home; non-smoker
A17: P15 | B17: Marcus Teo | C17: 57 | D17: Female | E17: Citizen | F17: Singapore | G17: Software Engineer | H17: 2 | J17: 5750 | K17: SGD | L17: conservative | M17: high | N17: TRUE | O17: TRUE | P17: B | Q17: Private | R17: FALSE | S17: Life style activities | T17: stress-free | U17: FALSE | V17: 92 | AD17: Software Engineer; age 57; Citizen; 2 dep; home; non-smoker
... A52: P50 | B52: Siti Lim | C52: 47 | D52: Female | E52: Foreigner | F52: Singapore | G52: Driver | H52: 2 | J52: 5000 | K52: SGD | L52: aggressive | M52: high | N52: TRUE | O52: FALSE | P52: A | Q52: Private | R52: TRUE | S52: Adventurous Sports | T52: only the best | U52: FALSE | V52: 90 | AD52: Driver; age 47; Foreigner; 2 dep; home; non-smoker

Sheet CPF
A1: CPF — social-security plug-in. In: gross, age, residency, country. Out: employee contribution, take-home. Runs in user currency.
A2: Selected persona | B2: =SelectedPersona | C2: =IFERROR(INDEX(Personas!B$3:B$52,MATCH($B$2,Personas!$A$3:$A$52,0)),"") | D2: Follows the dropdown on the Selected persona tab. | F2: A · INPUT DATA
A3: Attribute | B3: Value | C3: Kind | D3: Source / formula | F3: B · LLM PREDICTED DATA
A4: A · INPUT DATA — from the selected Personas row | F4: C · DETERMINISTICALLY CALCULATED | I4: D · MODULE PER COUNTRY — TRUE = SG-CPF module; FALSE = default module (no contribution)
A5: country | B5: =IFERROR(INDEX(Personas!F$3:F$52,MATCH($B$2,Personas!$A$3:$A$52,0)),"") | C5: A · input | D5: Personas F. Looks up the country switch. | F5: D · ASSUMPTIONS / SHARED DATA | I5: country | J5: CPF on? | K5: note
A6: residency | B6: =IFERROR(INDEX(Personas!E$3:E$52,MATCH($B$2,Personas!$A$3:$A$52,0)),"") | C6: A · input | D6: Personas E. When CPF is on, Foreigner → rate 0. | F6: E · USER / FRONTEND OVERRIDE | I6: Singapore | J6: TRUE | K6: src/cpf.py applies. Citizen / PR contribute; Foreigner rate 0.
A7: age | B7: =IFERROR(INDEX(Personas!C$3:C$52,MATCH($B$2,Personas!$A$3:$A$52,0)),"") | C7: A · input | D7: Personas C. Age-band rate when CPF is on. | I7: Vietnam | J7: FALSE | K7: No CPF. Take-home = gross.
A8: incomeMonthly | B8: =IFERROR(INDEX(Personas!J$3:J$52,MATCH($B$2,Personas!$A$3:$A$52,0)),"") | C8: A · input | D8: Personas J (LLM or user overwrite). | I8: Malaysia | J8: FALSE | K8: No CPF. Take-home = gross.
I9: Thailand | J9: FALSE | K9: No CPF. Take-home = gross.
A10: D · ASSUMPTIONS — src/cpf.py (used only when CPF is on) | I10: Philippines | J10: FALSE | K10: No CPF. Take-home = gross.
A11: OW_CEILING | B11: 8000 | C11: D · assumption / shared | D11: Ordinary-wage ceiling. Employee CPF is on min(gross, this). | I11: Australia | J11: FALSE | K11: No CPF. Take-home = gross.
A12: cpfRate_to55 | B12: 0.2 | C12: D · assumption / shared | D12: Employee rate age ≤ 55. | I12: Germany | J12: FALSE | K12: No CPF. Take-home = gross.
A13: cpfRate_to60 | B13: 0.18 | C13: D · assumption / shared | D13: Age 56–60. | I13: Hong Kong | J13: FALSE | K13: No CPF. Take-home = gross.
A14: cpfRate_to65 | B14: 0.125 | C14: D · assumption / shared | D14: Age 61–65. | I14: United States | J14: FALSE | K14: No CPF. Take-home = gross.
A15: cpfRate_to70 | B15: 0.075 | C15: D · assumption / shared | D15: Age 66–70.
A16: cpfRate_over70 | B16: 0.05 | C16: D · assumption / shared | D16: Age > 70.
A18: E · OVERRIDE — blank = country switch. TRUE / FALSE forces CPF on or off
A19: CPF on? (override) | C19: E · user / frontend override | D19: TRUE / FALSE / blank. Blank uses the country table.
A21: C · DETERMINISTICALLY CALCULATED — src/cpf.py when on; identity when off
A22: CPF on (effective) | B22: =IF(B19="",IFERROR(VLOOKUP(B5,CpfCountrySwitch,2,FALSE),FALSE),B19) | C22: C · calculated | D22: Country table, unless the orange override is set.
A23: module used | B23: =IF(B22=TRUE,"SG-CPF (src/cpf.py)","default: no contribution, take-home = gross") | C23: C · calculated | D23: Plug-in interface. Other countries get their own module later; the rest of the model does not change.
A24: Singapore age-band rate | B24: =IF(LOWER(B6)="foreigner",0,IF(B7<=55,cpfRate_to55,IF(B7<=60,cpfRate_to60,IF(B7<=65,cpfRate_to65,IF(B7<=70,cpfRate_to70,cpfRate_over70))))) | C24: C · calculated | D24: employee_cpf_rate. Ignored when CPF is off.
A25: CPF rate used | B25: =IF(B22=TRUE,B24,0) | C25: C · calculated | D25: 0 when CPF is off for this country.
A26: employee CPF | B26: =IF(OR(B22<>TRUE,B8<=0,B25<=0),0,FLOOR(MIN(B8,OW_CEILING)*B25,1)) | C26: C · calculated | D26: floor(min(gross, ceiling) × rate). 0 if CPF off.
A27: take-home | B27: =IF(B8<=0,0,ROUND(MAX(0,B8-B26),2)) | C27: C · calculated | D27: Gross minus employee CPF. Equals income when CPF is off.

Sheet People Like You
A1: People Like You — selected persona. Spend, assets, home, life cover. Take-home comes from the CPF tab.
A2: Selected persona | B2: =SelectedPersona | C2: =IFERROR(INDEX(Personas!B$3:B$52,MATCH($B$2,Personas!$A$3:$A$52,0)),"") | D2: Follows the dropdown on the Selected persona tab. | F2: A · INPUT DATA
A3: Attribute | B3: Value | C3: Kind | D3: Source / formula | F3: B · LLM PREDICTED DATA
A4: A · INPUT DATA — About you from the selected Personas row | F4: C · DETERMINISTICALLY CALCULATED
A5: age | B5: =IFERROR(INDEX(Personas!C$3:C$52,MATCH($B$2,Personas!$A$3:$A$52,0)),"") | C5: A · input | D5: Personas C. Working years = age − 21. | F5: D · ASSUMPTIONS / SHARED DATA
A6: gender | B6: =IFERROR(INDEX(Personas!D$3:D$52,MATCH($B$2,Personas!$A$3:$A$52,0)),"") | C6: A · input | D6: Personas D. Not used by this component. | F6: E · USER / FRONTEND OVERRIDE
A7: residency | B7: =IFERROR(INDEX(Personas!E$3:E$52,MATCH($B$2,Personas!$A$3:$A$52,0)),"") | C7: A · input | D7: Personas E. Passed to the CPF tab (Foreigner → 0 when CPF is on).
A8: country | B8: =IFERROR(INDEX(Personas!F$3:F$52,MATCH($B$2,Personas!$A$3:$A$52,0)),"") | C8: A · input | D8: Personas F. CPF on/off is decided on the CPF tab.
A9: occupation | B9: =IFERROR(INDEX(Personas!G$3:G$52,MATCH($B$2,Personas!$A$3:$A$52,0)),"") | C9: A · input | D9: Personas G. Looks up income_anchors.json Singapore band.
A10: dependents | B10: =IFERROR(INDEX(Personas!H$3:H$52,MATCH($B$2,Personas!$A$3:$A$52,0)),"") | C10: A · input | D10: Personas H. Spend-share +5 pp each; 5× income life cover if > 0.
A11: maritalStatus (typed) | B11: =IFERROR(INDEX(Personas!I$3:I$52,MATCH($B$2,Personas!$A$3:$A$52,0)),"") | C11: A · input | D11: Personas I. Blank → infer below.
A13: B · LLM PREDICTED DATA — fields this component reads from Personas
A14: income (LLM gross monthly) | B14: =IFERROR(INDEX(Personas!J$3:J$52,MATCH($B$2,Personas!$A$3:$A$52,0)),"") | C14: B · LLM predicted | D14: Personas J. people_like_you_all_fields.json income.
A15: currency | B15: =IFERROR(INDEX(Personas!K$3:K$52,MATCH($B$2,Personas!$A$3:$A$52,0)),"") | C15: B · LLM predicted | D15: Personas K. SGD in this workbook.
A16: property (owns home) | B16: =IFERROR(INDEX(Personas!N$3:N$52,MATCH($B$2,Personas!$A$3:$A$52,0)),"") | C16: B · LLM predicted | D16: Personas N. seed_property_value if TRUE.
A17: life_expectancy (raw) | B17: =IFERROR(INDEX(Personas!V$3:V$52,MATCH($B$2,Personas!$A$3:$A$52,0)),"") | C17: B · LLM predicted | D17: Personas V. Capped at 99. Missing or ≤ 0 → 85.
A19: D · ASSUMPTIONS / SHARED DATA — named cells on Assumptions (CPF is on the CPF tab)
A20: spendShareBase | B20: =spendShareBase | C20: D · assumption / shared | D20: 67.5% of take-home.
A21: spendSharePerDependant | B21: =spendSharePerDependant | C21: D · assumption / shared | D21: +5 pp per dependant.
A22: spendShareCap | B22: =spendShareCap | C22: D · assumption / shared | D22: 90% cap.
A23: assetsSaveShare | B23: =assetsSaveShare | C23: D · assumption / shared | D23: 50% of annual surplus saved.
A24: workStartAge | B24: =workStartAge | C24: D · assumption / shared | D24: 21. Working years = max(0, age − 21).
A25: CASH_SAVINGS_SHARE | B25: =CASH_SAVINGS_SHARE | C25: D · assumption / shared | D25: src/predict.py 15% cash.
A26: INVESTMENTS_SHARE | B26: =INVESTMENTS_SHARE | C26: D · assumption / shared | D26: src/predict.py 85%.
A27: liabilityRatio | B27: =liabilityRatio | C27: D · assumption / shared | D27: PLU liabilities = liquid assets × 0.7 (not the mortgage).
A28: propertyLow (USD) | B28: =propertyLow | C28: D · assumption / shared | D28: income < propertyIncomeLow (USD).
A29: propertyMid (USD) | B29: =propertyMid | C29: D · assumption / shared | D29: income between the two USD bands.
A30: propertyHigh (USD) | B30: =propertyHigh | C30: D · assumption / shared | D30: income > propertyIncomeHigh (USD).
A31: propertyIncomeLow (USD) | B31: =propertyIncomeLow | C31: D · assumption / shared | D31: Monthly gross income in USD.
A32: propertyIncomeHigh (USD) | B32: =propertyIncomeHigh | C32: D · assumption / shared | D32: Monthly gross income in USD.
A33: PROPERTY_LTV | B33: =PROPERTY_LTV | C33: D · assumption / shared | D33: Mortgage = round(property × 55%).
A34: lifePremiumRate | B34: =lifePremiumRate | C34: D · assumption / shared | D34: 0.31% of sum assured.
A35: life cover step (user currency) | B35: =FX_lifeRound | C35: D · assumption / shared | D35: lifeRoundUnit (USD) as a nice step in user currency (FX tab).
A36: lifeExpectancyDefault | B36: =lifeExpectancyDefault | C36: D · assumption / shared | D36: Used when raw LE is missing or ≤ 0.
A38: C · DETERMINISTICALLY CALCULATED — _apply_plu. Take-home is read from the CPF tab.
A39: band min | B39: =IFERROR(INDEX(Assumptions!$K$6:$K$13,MATCH(B9,Assumptions!$J$6:$J$13,0)),"") | C39: C · calculated | D39: income_anchors.json Singapore min for occupation.
A40: band max | B40: =IFERROR(INDEX(Assumptions!$L$6:$L$13,MATCH(B9,Assumptions!$J$6:$J$13,0)),"") | C40: C · calculated | D40: income_anchors.json Singapore max.
A41: incomeMonthly (clamped) | B41: =IF(OR(B39="",B14=0),B14,MIN(MAX(B14,B39),B40)) | C41: C · calculated | D41: Clamp LLM income into the occupation band. 0 stays 0.
A42: CPF on (from CPF tab) | B42: =CPF_on | C42: A · input | D42: Country switch or orange override on the CPF tab.
A43: CPF rate | B43: =CPF_rate | C43: C · calculated | D43: 0 when CPF is off for this country.
...

Sheet Need Profiler
A1: Need Profiler — selected persona. Weighted scores → two protection + N_RET + one growth. Parked coverage needs are scored only.
A2: Selected persona | B2: =SelectedPersona | C2: =IFERROR(INDEX(Personas!B$3:B$52,MATCH($B$2,Personas!$A$3:$A$52,0)),"") | D2: Follows the dropdown on the Selected persona tab. | F2: A · INPUT DATA
A3: Attribute | B3: Value | C3: Kind | D3: Source / formula | F3: B · LLM PREDICTED DATA
A4: A · INPUT DATA — from selected Personas + People Like You results | F4: C · DETERMINISTICALLY CALCULATED
A5: age | B5: =IFERROR(INDEX(Personas!C$3:C$52,MATCH($B$2,Personas!$A$3:$A$52,0)),"") | C5: A · input | D5: Personas C. Bucket <21 / ≤30 / ≤40 / else. | F5: D · ASSUMPTIONS / SHARED DATA
A6: gender | B6: =IFERROR(INDEX(Personas!D$3:D$52,MATCH($B$2,Personas!$A$3:$A$52,0)),"") | C6: A · input | D6: Personas D. male=3, female=2. | F6: E · USER / FRONTEND OVERRIDE
A7: dependents | B7: =IFERROR(INDEX(Personas!H$3:H$52,MATCH($B$2,Personas!$A$3:$A$52,0)),"") | C7: A · input | D7: Personas H. 0 / 1 / ≥2 → 0 / 2 / 4.
A8: occupation | B8: =IFERROR(INDEX(Personas!G$3:G$52,MATCH($B$2,Personas!$A$3:$A$52,0)),"") | C8: A · input | D8: Personas G. Self-employed tokens → 2, else 1.
A9: incomeMonthly (from PLU) | B9: =PLU_incomeMonthly | C9: A · input | D9: People Like You calculated income, used as profiler Income.
A10: expenseMonthly (from PLU) | B10: =PLU_expenseMonthly | C10: A · input | D10: People Like You calculated spend.
A11: liquid assets (from PLU) | B11: =PLU_cash+PLU_investments | C11: A · input | D11: cash + investments.
A12: PLU liabilities (from PLU) | B12: =PLU_liabilities | C12: A · input | D12: Not the mortgage.
A14: B · LLM PREDICTED DATA — lifestyle flags this component reads
A15: is_smoker | B15: =IFERROR(INDEX(Personas!U$3:U$52,MATCH($B$2,Personas!$A$3:$A$52,0)),"") | C15: B · LLM predicted | D15: Personas U. TRUE→3, else 1 (JSON has no Smoking options).
A16: hospitalization_type | B16: =IFERROR(INDEX(Personas!Q$3:Q$52,MATCH($B$2,Personas!$A$3:$A$52,0)),"") | C16: B · LLM predicted | D16: Personas Q. private=4, public=2.
A17: ward_type | B17: =IFERROR(INDEX(Personas!P$3:P$52,MATCH($B$2,Personas!$A$3:$A$52,0)),"") | C17: B · LLM predicted | D17: Personas P. A=3, B=2. Single/Double/Ward score 0.
A18: retirement_lifestyle | B18: =IFERROR(INDEX(Personas!T$3:T$52,MATCH($B$2,Personas!$A$3:$A$52,0)),"") | C18: B · LLM predicted | D18: Personas T. frugal / stress-free / only the best.
A19: sports | B19: =IFERROR(INDEX(Personas!S$3:S$52,MATCH($B$2,Personas!$A$3:$A$52,0)),"") | C19: B · LLM predicted | D19: Personas S. Adventurous / I dont do sports / Life style.
A20: property (owns home) | B20: =IFERROR(INDEX(Personas!N$3:N$52,MATCH($B$2,Personas!$A$3:$A$52,0)),"") | C20: B · LLM predicted | D20: Personas N. V0-16: no longer swaps N_SAV / N_PRP (not used for selection).
A22: D · ASSUMPTIONS / SHARED DATA — used by this component
A23: Existing hospital cover | B23: 0 | C23: D · assumption / shared | D23: build_profiler_profile hard-codes Existing*Coverage = False → option weight 1.
A24: Existing disability cover | B24: 0 | C24: D · assumption / shared | D24: Same. Stored as 0 here; option weight of False is 1.
A25: PPP-USD per 1 local (market ÷ price level) | B25: =FX_pppUsdPerLocal | C25: D · assumption / shared | D25: From the FX tab. Income / expense / assets / liabilities convert local × this rate (equals the market rate for the base country).
A26: Selection rule | B26: 2 prot + N_RET + 1 growth | C26: D · assumption / shared | D26: V0-16: protection from N_INC/N_CRI/N_TPD/N_HOS/N_PAC; growth N_EDU vs N_SAV. N_PRP is never auto-picked (no profiler label).
A27: Profiler weight matrix | B27: Assumptions!B90:L104 | C27: D · assumption / shared | D27: Need_profiler.json needs_factor_weights. SUMPRODUCT with option weights.
A29: C · DETERMINISTICALLY CALCULATED — local × FX → USD, then 15 option weights
A30: usd Income | B30: =IF(FX_usdPerLocal="","",PLU_incomeMonthly*FX_pppUsdPerLocal) | C30: C · calculated | D30: local income × PPP-USD rate (market USD ÷ price level, V0-22). Singapore = market USD.
A31: usd Expense | B31: =IF(FX_usdPerLocal="","",PLU_expenseMonthly*FX_pppUsdPerLocal) | C31: C · calculated | D31: local expense × FX.
A32: usd Assets | B32: =IF(FX_usdPerLocal="","",(PLU_cash+PLU_investments)*FX_pppUsdPerLocal) | C32: C · calculated | D32: cash + investments × FX.
A33: usd Liab | B33: =IF(FX_usdPerLocal="","",PLU_liabilities*FX_pppUsdPerLocal) | C33: C · calculated | D33: PLU liabilities × FX.
A34: ow Age | B34: =IF(B5<21,1,IF(B5<=30,2,IF(B5<=40,3,4))) | C34: C · calculated | D34: _get_option_weight Date of Birth.
A35: ow Gender | B35: =IF(LOWER(B6)="male",3,IF(LOWER(B6)="female",2,0)) | C35: C · calculated | D35: male=3, female=2.
A36: ow Deps | B36: =IF(B7=0,0,IF(B7=1,2,4)) | C36: C · calculated | D36: 0 / 1 / else.
A37: ow Occ | B37: =IF(OR(ISNUMBER(SEARCH("self",B8)),ISNUMBER(SEARCH("entrepreneur",B8)),ISNUMBER(SEARCH("own business",B8)),ISNUMBER(SEARCH("freelance",B8))),2,1) | C37: C · calculated | D37: Self-employed tokens.
A38: ow Smoke | B38: =IF(B15=TRUE,3,1) | C38: C · calculated | D38: No Smoking options in JSON.
A39: ow Income | B39: =IF(B30<1000,4,IF(B30<2500,3,IF(B30<5000,2,IF(B30<10000,1,0)))) | C39: C · calculated | D39: Need_profiler.json Income lt bands (USD after FX).
A40: ow Expense | B40: =IF(B31<600,4,IF(B31<1500,3,IF(B31<3000,2,IF(B31<6000,1,0)))) | C40: C · calculated | D40: Expense USD bands (~0.6× income).
A41: ow Assets | B41: =IF(B32<10000,4,IF(B32<50000,3,IF(B32<150000,2,IF(B32<500000,1,0)))) | C41: C · calculated | D41: Assets USD bands (stock).
A42: ow Liab | B42: =IF(B33<5000,4,IF(B33<25000,3,IF(B33<100000,2,IF(B33<250000,1,0)))) | C42: C · calculated | D42: Liabilities USD bands (stock).
A43: ow HospExist | B43: 1 | C43: C · calculated | D43: Existing hospital coverage always False → 1.
...

Sheet Need Calculator
A1: Need Calculator — selected persona. Runs in USD (S-block), results back in user currency. Orange cells are goal-card sliders (user currency).
A2: Selected persona | B2: =SelectedPersona | C2: =IFERROR(INDEX(Personas!B$3:B$52,MATCH($B$2,Personas!$A$3:$A$52,0)),"") | D2: Follows the dropdown on the Selected persona tab. | F2: A · INPUT DATA
A3: Attribute | B3: Value | C3: Kind | D3: Source / formula | F3: B · LLM PREDICTED DATA
A4: A · INPUT DATA — from Personas, People Like You, and Need Profiler | F4: C · DETERMINISTICALLY CALCULATED
A5: age | B5: =IFERROR(INDEX(Personas!C$3:C$52,MATCH($B$2,Personas!$A$3:$A$52,0)),"") | C5: A · input | D5: Personas C. | F5: D · ASSUMPTIONS / SHARED DATA
A6: incomeMonthly (from PLU) | B6: =PLU_incomeMonthly | C6: A · input | D6: Clamped gross monthly. | F6: E · USER / FRONTEND OVERRIDE
A7: expenseMonthly (from PLU) | B7: =PLU_expenseMonthly | C7: A · input | D7: Annual spend = this × 12.
A8: mortgage (from PLU) | B8: =PLU_mortgage | C8: A · input | D8: Added to N_INC amount.
A9: life sum (from PLU) | B9: =PLU_lifeSum | C9: A · input | D9: N_INC have.
A10: investments (from PLU) | B10: =PLU_investments | C10: A · input | D10: Tagged wealth pot only. Cash is never allocated.
A11: lifeExpectancy used (from PLU) | B11: =PLU_leUsed | C11: A · input | D11: yearsInRet = max(0, LE − retAge).
A13: O · GOAL-CARD SLIDERS / OVERRIDES — orange. Blank years keep the age rule
A14: lifestyle (1/2/3) | B14: 2 | C14: E · user / frontend override | D14: 1=frugal, 2=stress-free, 3=only the best. Default 2.
A15: retAge | B15: =ageOfRetirement | C15: E · user / frontend override | D15: Default from Assumptions (65).
A16: targetYear N_EDU | B16: =currentYear+MAX(1,EDU_TARGET_AGE-B5) | C16: E · user / frontend override | D16: Default: the year the customer turns EDU_TARGET_AGE (50); next year if older.
A17: targetYear N_SAV | B17: =currentYear+MAX(1,SAV_TARGET_AGE-B5) | C17: E · user / frontend override | D17: Default: the year the customer turns SAV_TARGET_AGE (40); next year if older.
A18: targetYear N_PRP | B18: =currentYear+MAX(1,PRP_TARGET_AGE-B5) | C18: E · user / frontend override | D18: Default: the year the customer turns PRP_TARGET_AGE (33); next year if older.
A19: bequest | B19: 0 | C19: E · user / frontend override | D19: Added to N_INC amount.
A20: dependYears (blank = age rule) | C20: E · user / frontend override | D20: Blank or ≤0 → supportYears.
A21: incomeReplace (blank = income) | C21: E · user / frontend override | D21: Blank → incomeMonthly for CI / TPD.
A22: N_SAV stored | B22: 0 | C22: E · user / frontend override | D22: If > 0, this is N_SAV amount; else 1× annual income.
A23: N_PRP stored | B23: 0 | C23: E · user / frontend override | D23: If > 0, this is N_PRP amount; else 5× annual income.
A24: tag N_RET | B24: 0 | C24: E · user / frontend override | D24: Investments tagged to retirement, then grown at realReturn.
A25: tag N_EDU | B25: 0 | C25: E · user / frontend override | D25: apply_investment_pot walk order: RET, EDU, SAV, PRP.
A26: tag N_SAV | B26: 0 | C26: E · user / frontend override | D26: Takes from remaining investments after RET and EDU.
A27: tag N_PRP | B27: 0 | C27: E · user / frontend override | D27: Last in the walk.
A28: LTC start age | B28: =LTC_START_AGE | C28: E · user / frontend override | D28: N_LTC front-end input. Default LTC_START_AGE (80).
A30: S · SYSTEM CURRENCY (USD) — user-currency inputs × USD per 1. The calculator below runs on these
A31: USD per 1 user-currency unit | B31: =FX_usdPerLocal | C31: D · assumption / shared | D31: FX tab. #N/A if the currency is unknown.
A32: price level (option B) | B32: =FX_priceLevel | C32: D · assumption / shared | D32: 1 under option A. Scales the USD fixed amounts.
A33: incomeMonthly USD | B33: =PLU_incomeMonthly*B31 | C33: C · calculated
A34: expenseMonthly USD | B34: =PLU_expenseMonthly*B31 | C34: C · calculated
A35: mortgage USD | B35: =PLU_mortgage*B31 | C35: C · calculated
A36: life sum USD | B36: =PLU_lifeSum*B31 | C36: C · calculated
A37: investments USD | B37: =PLU_investments*B31 | C37: C · calculated
A38: bequest USD | B38: =B19*B31 | C38: C · calculated
A39: N_SAV stored USD | B39: =B22*B31 | C39: C · calculated
A40: N_PRP stored USD | B40: =B23*B31 | C40: C · calculated
A41: tag N_RET USD | B41: =B24*B31 | C41: C · calculated
A42: tag N_EDU USD | B42: =B25*B31 | C42: C · calculated
...

Sheet Plan Calculator
A1: Plan Calculator — selected persona. seedProducts / planProducts.ts. Suggested = enabled AND gap > 0.
A2: Selected persona | B2: =SelectedPersona | C2: =IFERROR(INDEX(Personas!B$3:B$52,MATCH($B$2,Personas!$A$3:$A$52,0)),"") | D2: Follows the dropdown on the Selected persona tab. | F2: A · INPUT DATA
A3: Attribute | B3: Value | C3: Kind | D3: Source / formula | F3: B · LLM PREDICTED DATA
A4: A · INPUT DATA — from People Like You and Need Calculator | F4: C · DETERMINISTICALLY CALCULATED
A5: take-home (from PLU) | B5: =PLU_takeHome | C5: A · input | D5: Surplus uses take-home, not gross income. | F5: D · ASSUMPTIONS / SHARED DATA
A6: expenseMonthly (from PLU) | B6: =PLU_expenseMonthly | C6: A · input | D6: types.ts availableBudget. | F6: E · USER / FRONTEND OVERRIDE
A7: N_INC on (from Need Calculator) | B7: =NC_on_N_INC | C7: A · input | D7: Effective enable after Need Calculator override.
A8: N_INC gap (from Need Calculator) | B8: =NC_gap_N_INC | C8: A · input | D8: remaining_gap.
A9: N_CRI on (from Need Calculator) | B9: =NC_on_N_CRI | C9: A · input | D9: Effective enable after Need Calculator override.
A10: N_CRI gap (from Need Calculator) | B10: =NC_gap_N_CRI | C10: A · input | D10: remaining_gap.
A11: N_TPD on (from Need Calculator) | B11: =NC_on_N_TPD | C11: A · input | D11: Effective enable after Need Calculator override.
A12: N_TPD gap (from Need Calculator) | B12: =NC_gap_N_TPD | C12: A · input | D12: remaining_gap.
A13: N_HOS on (from Need Calculator) | B13: =NC_on_N_HOS | C13: A · input | D13: Effective enable after Need Calculator override.
A14: N_HOS gap (from Need Calculator) | B14: =NC_gap_N_HOS | C14: A · input | D14: remaining_gap.
A15: N_PAC on (from Need Calculator) | B15: =NC_on_N_PAC | C15: A · input | D15: Effective enable after Need Calculator override.
A16: N_PAC gap (from Need Calculator) | B16: =NC_gap_N_PAC | C16: A · input | D16: remaining_gap.
A17: N_LTC on (from Need Calculator) | B17: =NC_on_N_LTC | C17: A · input | D17: Effective enable after Need Calculator override.
A18: N_LTC gap (from Need Calculator) | B18: =NC_gap_N_LTC | C18: A · input | D18: remaining_gap.
A19: N_RET on (from Need Calculator) | B19: =NC_on_N_RET | C19: A · input | D19: Effective enable after Need Calculator override.
A20: N_RET gap (from Need Calculator) | B20: =NC_gap_N_RET | C20: A · input | D20: remaining_gap.
A21: N_EDU on (from Need Calculator) | B21: =NC_on_N_EDU | C21: A · input | D21: Effective enable after Need Calculator override.
A22: N_EDU gap (from Need Calculator) | B22: =NC_gap_N_EDU | C22: A · input | D22: remaining_gap.
A23: N_SAV on (from Need Calculator) | B23: =NC_on_N_SAV | C23: A · input | D23: Effective enable after Need Calculator override.
A24: N_SAV gap (from Need Calculator) | B24: =NC_gap_N_SAV | C24: A · input | D24: remaining_gap.
A25: N_PRP on (from Need Calculator) | B25: =NC_on_N_PRP | C25: A · input | D25: Effective enable after Need Calculator override.
A26: N_PRP gap (from Need Calculator) | B26: =NC_gap_N_PRP | C26: A · input | D26: remaining_gap.
A27: yearsToRet (from Need Calculator) | B27: =NC_yearsToRet | C27: A · input | D27: Retirement contribution horizon.
A28: eduYears (from Need Calculator) | B28: =NC_eduYears | C28: A · input | D28: N_EDU contribution horizon.
A29: savYears (from Need Calculator) | B29: =NC_savYears | C29: A · input | D29: N_SAV contribution horizon.
A30: prpYears (from Need Calculator) | B30: =NC_prpYears | C30: A · input | D30: N_PRP contribution horizon.
A32: D · ASSUMPTIONS / SHARED DATA
A33: protectionPremiumRate | B33: =protectionPremiumRate | C33: D · assumption / shared | D33: Dummy 0.00078. Future: premium-quote calculator API.
A34: FREE_BUDGET_SHARE | B34: =FREE_BUDGET_SHARE | C34: D · assumption / shared | D34: Half of leftover surplus split across wealth needs.
A35: monthly step (user currency) | B35: =FX_monthlyStep | C35: D · assumption / shared | D35: monthlyRoundStep (USD) as a nice step in user currency. SGD: 50.
A36: premium step (user currency) | B36: =FX_coverPremStep | C36: D · assumption / shared | D36: coverPremRoundStep (USD) as a nice step in user currency. SGD: 10.
A37: realReturn | B37: =realReturn | C37: D · assumption / shared | D37: annualPmtToHitFv for the wealth cap.
A39: C · DETERMINISTICALLY CALCULATED — suggested flags and protection sizing
A40: sug N_INC | B40: =AND(NC_on_N_INC,NC_gap_N_INC>0) | C40: C · calculated | D40: enabled AND gap > 0.
A41: sug N_CRI | B41: =AND(NC_on_N_CRI,NC_gap_N_CRI>0) | C41: C · calculated | D41: enabled AND gap > 0.
A42: sug N_TPD | B42: =AND(NC_on_N_TPD,NC_gap_N_TPD>0) | C42: C · calculated | D42: enabled AND gap > 0.
...

Sheet Budget Calculator
A1: Budget Calculator — selected persona. planAfford. Surplus is take-home minus expense.
A2: Selected persona | B2: =SelectedPersona | C2: =IFERROR(INDEX(Personas!B$3:B$52,MATCH($B$2,Personas!$A$3:$A$52,0)),"") | D2: Follows the dropdown on the Selected persona tab. | F2: A · INPUT DATA
A3: Attribute | B3: Value | C3: Kind | D3: Source / formula | F3: B · LLM PREDICTED DATA
A4: A · INPUT DATA — from People Like You and Plan Calculator | F4: C · DETERMINISTICALLY CALCULATED
A5: take-home (from PLU) | B5: =PLU_takeHome | C5: A · input | D5: types.ts availableBudget uses take-home. | F5: D · ASSUMPTIONS / SHARED DATA
A6: expenseMonthly (from PLU) | B6: =PLU_expenseMonthly | C6: A · input | D6: Not gross income. | F6: E · USER / FRONTEND OVERRIDE
A7: investments (from PLU) | B7: =PLU_investments | C7: A · input | D7: Cap for lumps.
A8: included N_INC premium | B8: =IF(PLAN_included_N_INC,PLAN_prem_N_INC,0) | C8: A · input | D8: Only included protection.
A9: included N_CRI premium | B9: =IF(PLAN_included_N_CRI,PLAN_prem_N_CRI,0) | C9: A · input
A10: included N_TPD premium | B10: =IF(PLAN_included_N_TPD,PLAN_prem_N_TPD,0) | C10: A · input
A11: included N_HOS premium | B11: =IF(PLAN_included_N_HOS,PLAN_prem_N_HOS,0) | C11: A · input
A12: included N_PAC premium | B12: =IF(PLAN_included_N_PAC,PLAN_prem_N_PAC,0) | C12: A · input | D12: V0-16.
A13: included N_LTC premium | B13: =IF(PLAN_included_N_LTC,PLAN_prem_N_LTC,0) | C13: A · input | D13: V0-19.
A14: investMth (from Plan) | B14: =PLAN_investMth | C14: A · input | D14: Included wealth contributions.
A15: investLump (from Plan) | B15: =PLAN_investLump | C15: A · input | D15: Included wealth lumps.
A17: D · ASSUMPTIONS / SHARED DATA
A18: FREE_BUDGET_SHARE | B18: =FREE_BUDGET_SHARE | C18: D · assumption / shared | D18: Half of monthly surplus is the free budget.
A20: C · DETERMINISTICALLY CALCULATED — planAfford
A21: available | B21: =MAX(0,PLU_takeHome-PLU_expenseMonthly) | C21: C · calculated | D21: max(0, take-home − expense).
A22: free (50%) | B22: =ROUND(B21*FREE_BUDGET_SHARE,0) | C22: C · calculated | D22: available × 50%, rounded.
A23: included prot prem / yr | B23: =IF(PLAN_included_N_INC,PLAN_prem_N_INC,0)+IF(PLAN_included_N_CRI,PLAN_prem_N_CRI,0)+IF(PLAN_included_N_TPD,PLAN_prem_N_TPD,0)+IF(PLAN_included_N_HOS,PLAN_prem_N_HOS,0)+IF(PLAN_included_N_PAC,PLAN_prem_N_PAC,0)+IF(PLAN_included_N_LTC,PLAN_prem_N_LTC,0) | C23: C · calculated | D23: Sum of included protection premiums.
A24: premMth (display) | B24: =ROUND(B23/12,0) | C24: C · calculated | D24: Annual premiums / 12.
A25: contribMth | B25: =PLAN_investMth | C25: C · calculated | D25: Same as investMth.
A26: monthly | B26: =ROUND(PLAN_investMth+B23/12,0) | C26: C · calculated | D26: contrib + prem/12.
A27: monthlyOver | B27: =B26-B22 | C27: C · calculated | D27: > 0 means the plan exceeds the free budget.
A28: lumps | B28: =PLAN_investLump | C28: C · calculated | D28: Included lumps.
A29: lumpOver | B29: =B28-PLU_investments | C29: C · calculated | D29: > 0 means lumps exceed current investments.

Sheet Scenario Visualizer
A1: Scenario Visualizer — selected persona. One deterministic path of SV CashFlowGeneratorV2 on GP's payload.
A2: Selected persona | B2: =SelectedPersona | C2: =IFERROR(INDEX(Personas!B$3:B$52,MATCH($B$2,Personas!$A$3:$A$52,0)),"") | D2: Follows the dropdown on the Selected persona tab. | F2: A · INPUT DATA
A3: Attribute | B3: Value | C3: Kind | D3: Source / formula | F3: B · LLM PREDICTED DATA
A4: A · INPUT DATA — effective session (People Like You, Need Calculator, Plan Calculator) | F4: C · DETERMINISTICALLY CALCULATED | H4: D · SV CPF TABLES — SocialSecurityR_SGP (by age at contribution)
A5: age | B5: =IFERROR(INDEX(Personas!C$3:C$52,MATCH($B$2,Personas!$A$3:$A$52,0)),"") | C5: A · input | D5: Personas C. | F5: D · ASSUMPTIONS / SHARED DATA | H5: from age | I5: to age | J5: total rate | K5: employee rate | L5: OA share | M5: SA share | N5: MA share
A6: residency | B6: =IFERROR(INDEX(Personas!E$3:E$52,MATCH($B$2,Personas!$A$3:$A$52,0)),"") | C6: A · input | D6: Personas E. sv_payload.py sends CPF region R_SGP unless Foreigner. | F6: E · USER / FRONTEND OVERRIDE | H6: 0 | I6: 35 | J6: 0.37 | K6: 0.2 | L6: 0.6217 | M6: 0.1621 | N6: 0.2162
A7: incomeMonthly | B7: =PLU_incomeMonthly | C7: A · input | D7: Salary I_SAL = round(× 12). | H7: 36 | I7: 45 | J7: 0.37 | K7: 0.2 | L7: 0.5677 | M7: 0.1891 | N7: 0.2432
A8: take-home | B8: =PLU_takeHome | C8: A · input | D8: Investment contribution = take-home − spend. | H8: 46 | I8: 50 | J8: 0.37 | K8: 0.2 | L8: 0.5136 | M8: 0.2162 | N8: 0.2702
A9: expenseMonthly | B9: =PLU_expenseMonthly | C9: A · input | D9: PERSONAL_EXPENSE = round(× 12). | H9: 51 | I9: 55 | J9: 0.37 | K9: 0.2 | L9: 0.4055 | M9: 0.3108 | N9: 0.2837
A10: cash | B10: =PLU_cash | C10: A · input | D10: A_SAV, grows at interestRate. | H10: 56 | I10: 60 | J10: 0.325 | K10: 0.17 | L10: 0.4069 | M10: 0.2372 | N10: 0.3559
A11: investments | B11: =PLU_investments | C11: A · input | D11: INVESTMENT_PORTFOLIO, grows at investmentReturn. | H11: 61 | I11: 65 | J11: 0.235 | K11: 0.115 | L11: 0.1709 | M11: 0.317 | N11: 0.5121
A12: property | B12: =PLU_property | C12: A · input | D12: RESIDENTIAL_PROPERTY (illiquid). | H12: 66 | I12: 70 | J12: 0.165 | K12: 0.075 | L12: 0.0646 | M12: 0.258 | N12: 0.6774
A13: mortgage | B13: =PLU_mortgage | C13: A · input | D13: Mortgage loan, 20-year annuity at loanRate. | H13: 71 | I13: 999 | J13: 0.125 | K13: 0.05 | L13: 0.08 | M13: 0.08 | N13: 0.84
A14: life sum assured | B14: =PLU_lifeSum | C14: A · input | D14: Existing life policy (only when > 0).
A15: life premium / yr | B15: =PLU_lifePrem | C15: A · input | D15: regularPremium of the existing policy. | H15: D · CPF LIFE — BRS and monthly payout by (55 − age)+ + year − 2023
H16: row | I16: BRS | J16: payout × 1 | K16: payout × 2 | L16: payout × 3
A17: D · ASSUMPTIONS — SV helium tenant conf.ini and SocialSecurityR_SGP | H17: 0 | I17: 99400 | J17: 870 | K17: 1620 | L17: 2370
A18: path end age (sent: LON_AGE) | B18: =LON_AGE | C18: D · assumption / shared | D18: V0-21: GP sends the cap (99); was SV tenant 100. | H18: 1 | I18: 102900 | J18: 900 | K18: 1640 | L18: 2350
A19: savingsRate | B19: 0.01 | C19: D · assumption / shared | D19: helium conf.ini. Savings account growth; also the premium load (× 1.01). | H19: 2 | I19: 106500 | J19: 930 | K19: 1730 | L19: 2530
A20: ageOfRetirement | B20: =ageOfRetirement | C20: D · assumption / shared | D20: Assumptions. | H20: 3 | I20: 110200 | J20: 950 | K20: 1780 | L20: 2610
A21: loan / premium term (years) | B21: 20 | C21: D · assumption / shared | D21: Mortgage remainingYears and existing policyTerm in sv_payload.py. | H21: 4 | I21: 114100 | J21: 980 | K21: 1840 | L21: 2690
A22: property rate premium | B22: 0.004 | C22: D · assumption / shared | D22: Property grows at max(0, assetReturn + 0.4%).
A23: currency shock share | B23: 0.66666667 | C23: D · assumption / shared | D23: Liquid assets fall by 2/3 of the slider.
A24: CPF ordinary-wage cap / yr | B24: 96000 | C24: D · assumption / shared | D24: SocialSecurityR_SGP.
A25: CPF MA cap | B25: 63000 | C25: D · assumption / shared | D25: Medisave excess moves to RA at payout age; MA is capped from then.
A26: CPF OA rate | B26: 0.025 | C26: D · assumption / shared
A27: CPF SA / MA rate | B27: 0.04 | C27: D · assumption / shared
